Workbook

Sheet NYMTSP
A1: State | B1: cbsasub | C1: areaname | D1: median2025 | E1: lim50_25p1 | F1: lim50_25p2 | G1: lim50_25p3 | H1: lim50_25p4 | I1: lim50_25p5 | J1: lim50_25p6 | K1: lim50_25p7 | L1: lim50_25p8 | M1: Lim60_25p1 | N1: Lim60_25p2 | O1: Lim60_25p3 | P1: Lim60_25p4 | Q1: Lim60_25p5 | R1: Lim60_25p6 | S1: Lim60_25p7 | T1: Lim60_25p8 | U1: HERA_Lim_type25 | V1: Lim50_HERA_25p1 | W1: Lim50_HERA_25p2 | X1: Lim50_HERA_25p3 | Y1: Lim50_HERA_25p4 | Z1: Lim50_HERA_25p5 | AA1: Lim50_HERA_25p6 | AB1: Lim50_HERA_25p7 | AC1: Lim50_HERA_25p8 | AD1: Lim60_HERA_25p1 | AE1: Lim60_HERA_25p2 | AF1: Lim60_HERA_25p3 | AG1: Lim60_HERA_25p4 | AH1: Lim60_HERA_25p5 | AI1: Lim60_HERA_25p6 | AJ1: Lim60_HERA_25p7 | AK1: Lim60_HERA_25p8 | AL1: State | AM1: statename | AN1: metro | AO1: county_town_name | AP1: stusps | AQ1: county | AR1: county_name
A2: 36 | B2: METRO10580M10580 | C2: Albany-Schenectady-Troy, NY MSA | D2: 116100 | E2: 40650 | F2: 46450 | G2: 52250 | H2: 58050 | I2: 62700 | J2: 67350 | K2: 72000 | L2: 76650 | M2: 48780 | N2: 55740 | O2: 62700 | P2: 69660 | Q2: 75240 | R2: 80820 | S2: 86400 | T2: 91980 | U2: Regular | AL2: 36 | AM2: NEW YORK | AN2: 1 | AO2: Albany County | AP2: NY | AQ2: 001 | AR2: Albany County
A3: 36 | B3: NCNTY36003N36003 | C3: Allegany County, NY | D3: 86400 | E3: 31000 | F3: 35400 | G3: 39850 | H3: 44250 | I3: 47800 | J3: 51350 | K3: 54900 | L3: 58450 | M3: 37200 | N3: 42480 | O3: 47820 | P3: 53100 | Q3: 57360 | R3: 61620 | S3: 65880 | T3: 70140 | U3: Regular | AL3: 36 | AM3: NEW YORK | AN3: 0 | AO3: Allegany County | AP3: NY | AQ3: 003 | AR3: Allegany County
A4: 36 | B4: METRO35620MM5600 | C4: New York, NY HUD Metro FMR Area | D4: 103000 | E4: 56700 | F4: 64800 | G4: 72900 | H4: 81000 | I4: 87500 | J4: 94000 | K4: 100450 | L4: 106950 | M4: 68040 | N4: 77760 | O4: 87480 | P4: 97200 | Q4: 105000 | R4: 112800 | S4: 120540 | T4: 128340 | U4: Regular | AL4: 36 | AM4: NEW YORK | AN4: 1 | AO4: Bronx County | AP4: NY | AQ4: 005 | AR4: Bronx County
A5: 36 | B5: METRO13780M13780 | C5: Binghamton, NY MSA | D5: 94500 | E5: 33100 | F5: 37800 | G5: 42550 | H5: 47250 | I5: 51050 | J5: 54850 | K5: 58600 | L5: 62400 | M5: 39720 | N5: 45360 | O5: 51060 | P5: 56700 | Q5: 61260 | R5: 65820 | S5: 70320 | T5: 74880 | U5: Regular | AL5: 36 | AM5: NEW YORK | AN5: 1 | AO5: Broome County | AP5: NY | AQ5: 007 | AR5: Broome County
A6: 36 | B6: NCNTY36009N36009 | C6: Cattaraugus County, NY | D6: 77200 | E6: 31000 | F6: 35400 | G6: 39850 | H6: 44250 | I6: 47800 | J6: 51350 | K6: 54900 | L6: 58450 | M6: 37200 | N6: 42480 | O6: 47820 | P6: 53100 | Q6: 57360 | R6: 61620 | S6: 65880 | T6: 70140 | U6: Regular | AL6: 36 | AM6: NEW YORK | AN6: 0 | AO6: Cattaraugus County | AP6: NY | AQ6: 009 | AR6: Cattaraugus County
A7: 36 | B7: NCNTY36011N36011 | C7: Cayuga County, NY | D7: 83500 | E7: 31000 | F7: 35400 | G7: 39850 | H7: 44250 | I7: 47800 | J7: 51350 | K7: 54900 | L7: 58450 | M7: 37200 | N7: 42480 | O7: 47820 | P7: 53100 | Q7: 57360 | R7: 61620 | S7: 65880 | T7: 70140 | U7: Special | V7: 31650 | W7: 36150 | X7: 40650 | Y7: 45150 | Z7: 48800 | AA7: 52400 | AB7: 56000 | AC7: 59600 | AD7: 37980 | AE7: 43380 | AF7: 48780 | AG7: 54180 | AH7: 58560 | AI7: 62880 | AJ7: 67200 | AK7: 71520 | AL7: 36 | AM7: NEW YORK | AN7: 0 | AO7: Cayuga County | AP7: NY | AQ7: 011 | AR7: Cayuga County
A8: 36 | B8: NCNTY36013N36013 | C8: Chautauqua County, NY | D8: 82700 | E8: 31000 | F8: 35400 | G8: 39850 | H8: 44250 | I8: 47800 | J8: 51350 | K8: 54900 | L8: 58450 | M8: 37200 | N8: 42480 | O8: 47820 | P8: 53100 | Q8: 57360 | R8: 61620 | S8: 65880 | T8: 70140 | U8: Regular | AL8: 36 | AM8: NEW YORK | AN8: 0 | AO8: Chautauqua County | AP8: NY | AQ8: 013 | AR8: Chautauqua County
A9: 36 | B9: METRO21300M21300 | C9: Elmira, NY MSA | D9: 81900 | E9: 31000 | F9: 35400 | G9: 39850 | H9: 44250 | I9: 47800 | J9: 51350 | K9: 54900 | L9: 58450 | M9: 37200 | N9: 42480 | O9: 47820 | P9: 53100 | Q9: 57360 | R9: 61620 | S9: 65880 | T9: 70140 | U9: Regular | AL9: 36 | AM9: NEW YORK | AN9: 1 | AO9: Chemung County | AP9: NY | AQ9: 015 | AR9: Chemung County
A10: 36 | B10: NCNTY36017N36017 | C10: Chenango County, NY | D10: 83100 | E10: 31000 | F10: 35400 | G10: 39850 | H10: 44250 | I10: 47800 | J10: 51350 | K10: 54900 | L10: 58450 | M10: 37200 | N10: 42480 | O10: 47820 | P10: 53100 | Q10: 57360 | R10: 61620 | S10: 65880 | T10: 70140 | U10: Regular | AL10: 36 | AM10: NEW YORK | AN10: 0 | AO10: Chenango County | AP10: NY | AQ10: 017 | AR10: Chenango County
A11: 36 | B11: NCNTY36019N36019 | C11: Clinton County, NY | D11: 94300 | E11: 33050 | F11: 37750 | G11: 42450 | H11: 47150 | I11: 50950 | J11: 54700 | K11: 58500 | L11: 62250 | M11: 39660 | N11: 45300 | O11: 50940 | P11: 56580 | Q11: 61140 | R11: 65640 | S11: 70200 | T11: 74700 | U11: Regular | AL11: 36 | AM11: NEW YORK | AN11: 0 | AO11: Clinton County | AP11: NY | AQ11: 019 | AR11: Clinton County
A12: 36 | B12: NCNTY36021N36021 | C12: Columbia County, NY | D12: 113100 | E12: 39450 | F12: 45100 | G12: 50700 | H12: 56350 | I12: 60850 | J12: 65400 | K12: 69900 | L12: 74400 | M12: 47340 | N12: 54120 | O12: 60840 | P12: 67620 | Q12: 73020 | R12: 78480 | S12: 83880 | T12: 89280 | U12: Regular | AL12: 36 | AM12: NEW YORK | AN12: 0 | AO12: Columbia County | AP12: NY | AQ12: 021 | AR12: Columbia County
A13: 36 | B13: NCNTY36023N36023 | C13: Cortland County, NY | D13: 92200 | E13: 32300 | F13: 36900 | G13: 41500 | H13: 46100 | I13: 49800 | J13: 53500 | K13: 57200 | L13: 60900 | M13: 38760 | N13: 44280 | O13: 49800 | P13: 55320 | Q13: 59760 | R13: 64200 | S13: 68640 | T13: 73080 | U13: Regular | AL13: 36 | AM13: NEW YORK | AN13: 0 | AO13: Cortland County | AP13: NY | AQ13: 023 | AR13: Cortland County
A14: 36 | B14: NCNTY36025N36025 | C14: Delaware County, NY | D14: 82600 | E14: 31000 | F14: 35400 | G14: 39850 | H14: 44250 | I14: 47800 | J14: 51350 | K14: 54900 | L14: 58450 | M14: 37200 | N14: 42480 | O14: 47820 | P14: 53100 | Q14: 57360 | R14: 61620 | S14: 65880 | T14: 70140 | U14: Regular | AL14: 36 | AM14: NEW YORK | AN14: 0 | AO14: Delaware County | AP14: NY | AQ14: 025 | AR14: Delaware County
A15: 36 | B15: METRO28880M28880 | C15: Kiryas Joel-Poughkeepsie-Newburgh, NY MSA | D15: 123000 | E15: 43050 | F15: 49200 | G15: 55350 | H15: 61500 | I15: 66450 | J15: 71350 | K15: 76300 | L15: 81200 | M15: 51660 | N15: 59040 | O15: 66420 | P15: 73800 | Q15: 79740 | R15: 85620 | S15: 91560 | T15: 97440 | U15: Regular | AL15: 36 | AM15: NEW YORK | AN15: 1 | AO15: Dutchess County | AP15: NY | AQ15: 027 | AR15: Dutchess County
A16: 36 | B16: METRO15380M15380 | C16: Buffalo-Cheektowaga-Niagara Falls, NY MSA | D16: 101000 | E16: 35350 | F16: 40400 | G16: 45450 | H16: 50500 | I16: 54550 | J16: 58600 | K16: 62650 | L16: 66700 | M16: 42420 | N16: 48480 | O16: 54540 | P16: 60600 | Q16: 65460 | R16: 70320 | S16: 75180 | T16: 80040 | U16: Regular | AL16: 36 | AM16: NEW YORK | AN16: 1 | AO16: Erie County | AP16: NY | AQ16: 029 | AR16: Erie County
A17: 36 | B17: NCNTY36031N36031 | C17: Essex County, NY | D17: 91900 | E17: 32200 | F17: 36800 | G17: 41400 | H17: 45950 | I17: 49650 | J17: 53350 | K17: 57000 | L17: 60700 | M17: 38640 | N17: 44160 | O17: 49680 | P17: 55140 | Q17: 59580 | R17: 64020 | S17: 68400 | T17: 72840 | U17: Regular | AL17: 36 | AM17: NEW YORK | AN17: 0 | AO17: Essex County | AP17: NY | AQ17: 031 | AR17: Essex County
A18: 36 | B18: NCNTY36033N36033 | C18: Franklin County, NY | D18: 82100 | E18: 31000 | F18: 35400 | G18: 39850 | H18: 44250 | I18: 47800 | J18: 51350 | K18: 54900 | L18: 58450 | M18: 37200 | N18: 42480 | O18: 47820 | P18: 53100 | Q18: 57360 | R18: 61620 | S18: 65880 | T18: 70140 | U18: Regular | AL18: 36 | AM18: NEW YORK | AN18: 0 | AO18: Franklin County | AP18: NY | AQ18: 033 | AR18: Franklin County
A19: 36 | B19: NCNTY36035N36035 | C19: Fulton County, NY | D19: 79100 | E19: 31000 | F19: 35400 | G19: 39850 | H19: 44250 | I19: 47800 | J19: 51350 | K19: 54900 | L19: 58450 | M19: 37200 | N19: 42480 | O19: 47820 | P19: 53100 | Q19: 57360 | R19: 61620 | S19: 65880 | T19: 70140 | U19: Regular | AL19: 36 | AM19: NEW YORK | AN19: 0 | AO19: Fulton County | AP19: NY | AQ19: 035 | AR19: Fulton County
A20: 36 | B20: NCNTY36037N36037 | C20: Genesee County, NY | D20: 96900 | E20: 33950 | F20: 38800 | G20: 43650 | H20: 48450 | I20: 52350 | J20: 56250 | K20: 60100 | L20: 64000 | M20: 40740 | N20: 46560 | O20: 52380 | P20: 58140 | Q20: 62820 | R20: 67500 | S20: 72120 | T20: 76800 | U20: Special | V20: 35300 | W20: 40350 | X20: 45400 | Y20: 50400 | Z20: 54450 | AA20: 58500 | AB20: 62500 | AC20: 66550 | AD20: 42360 | AE20: 48420 | AF20: 54480 | AG20: 60480 | AH20: 65340 | AI20: 70200 | AJ20: 75000 | AK20: 79860 | AL20: 36 | AM20: NEW YORK | AN20: 0 | AO20: Genesee County | AP20: NY | AQ20: 037 | AR20: Genesee County
A21: 36 | B21: NCNTY36039N36039 | C21: Greene County, NY | D21: 104300 | E21: 35150 | F21: 40100 | G21: 45150 | H21: 50150 | I21: 54200 | J21: 58200 | K21: 62200 | L21: 66200 | M21: 42180 | N21: 48120 | O21: 54180 | P21: 60180 | Q21: 65040 | R21: 69840 | S21: 74640 | T21: 79440 | U21: Regular | AL21: 36 | AM21: NEW YORK | AN21: 0 | AO21: Greene County | AP21: NY | AQ21: 039 | AR21: Greene County
A22: 36 | B22: NCNTY36041N36041 | C22: Hamilton County, NY | D22: 94300 | E22: 33000 | F22: 37750 | G22: 42450 | H22: 47150 | I22: 50950 | J22: 54700 | K22: 58500 | L22: 62250 | M22: 39600 | N22: 45300 | O22: 50940 | P22: 56580 | Q22: 61140 | R22: 65640 | S22: 70200 | T22: 74700 | U22: Regular | AL22: 36 | AM22: NEW YORK | AN22: 0 | AO22: Hamilton County | AP22: NY | AQ22: 041 | AR22: Hamilton County
A23: 36 | B23: METRO46540M46540 | C23: Utica-Rome, NY MSA | D23: 89000 | E23: 31150 | F23: 35600 | G23: 40050 | H23: 44500 | I23: 48100 | J23: 51650 | K23: 55200 | L23: 58750 | M23: 37380 | N23: 42720 | O23: 48060 | P23: 53400 | Q23: 57720 | R23: 61980 | S23: 66240 | T23: 70500 | U23: Regular | AL23: 36 | AM23: NEW YORK | AN23: 1 | AO23: Herkimer County | AP23: NY | AQ23: 043 | AR23: Herkimer County
A24: 36 | B24: METRO48060M48060 | C24: Watertown-Fort Drum, NY MSA | D24: 83400 | E24: 31000 | F24: 35400 | G24: 39850 | H24: 44250 | I24: 47800 | J24: 51350 | K24: 54900 | L24: 58450 | M24: 37200 | N24: 42480 | O24: 47820 | P24: 53100 | Q24: 57360 | R24: 61620 | S24: 65880 | T24: 70140 | U24: Regular | AL24: 36 | AM24: NEW YORK | AN24: 1 | AO24: Jefferson County | AP24: NY | AQ24: 045 | AR24: Jefferson County
A25: 36 | B25: METRO35620MM5600 | C25: New York, NY HUD Metro FMR Area | D25: 103000 | E25: 56700 | F25: 64800 | G25: 72900 | H25: 81000 | I25: 87500 | J25: 94000 | K25: 100450 | L25: 106950 | M25: 68040 | N25: 77760 | O25: 87480 | P25: 97200 | Q25: 105000 | R25: 112800 | S25: 120540 | T25: 128340 | U25: Regular | AL25: 36 | AM25: NEW YORK | AN25: 1 | AO25: Kings County | AP25: NY | AQ25: 047 | AR25: Kings County
A26: 36 | B26: NCNTY36049N36049 | C26: Lewis County, NY | D26: 84400 | E26: 31000 | F26: 35400 | G26: 39850 | H26: 44250 | I26: 47800 | J26: 51350 | K26: 54900 | L26: 58450 | M26: 37200 | N26: 42480 | O26: 47820 | P26: 53100 | Q26: 57360 | R26: 61620 | S26: 65880 | T26: 70140 | U26: Regular | AL26: 36 | AM26: NEW YORK | AN26: 0 | AO26: Lewis County | AP26: NY | AQ26: 049 | AR26: Lewis County
A27: 36 | B27: METRO40380M40380 | C27: Rochester, NY HUD Metro FMR Area | D27: 103900 | E27: 36400 | F27: 41600 | G27: 46800 | H27: 51950 | I27: 56150 | J27: 60300 | K27: 64450 | L27: 68600 | M27: 43680 | N27: 49920 | O27: 56160 | P27: 62340 | Q27: 67380 | R27: 72360 | S27: 77340 | T27: 82320 | U27: Special | V27: 36750 | W27: 42000 | X27: 47250 | Y27: 52450 | Z27: 56650 | AA27: 60850 | AB27: 65050 | AC27: 69250 | AD27: 44100 | AE27: 50400 | AF27: 56700 | AG27: 62940 | AH27: 67980 | AI27: 73020 | AJ27: 78060 | AK27: 83100 | AL27: 36 | AM27: NEW YORK | AN27: 1 | AO27: Livingston County | AP27: NY | AQ27: 051 | AR27: Livingston County
A28: 36 | B28: METRO45060M45060 | C28: Syracuse, NY MSA | D28: 104100 | E28: 36250 | F28: 41400 | G28: 46600 | H28: 51750 | I28: 55900 | J28: 60050 | K28: 64200 | L28: 68350 | M28: 43500 | N28: 49680 | O28: 55920 | P28: 62100 | Q28: 67080 | R28: 72060 | S28: 77040 | T28: 82020 | U28: Special | V28: 36450 | W28: 41650 | X28: 46850 | Y28: 52050 | Z28: 56250 | AA28: 60400 | AB28: 64550 | AC28: 68750 | AD28: 43740 | AE28: 49980 | AF28: 56220 | AG28: 62460 | AH28: 67500 | AI28: 72480 | AJ28: 77460 | AK28: 82500 | AL28: 36 | AM28: NEW YORK | AN28: 1 | AO28: Madison County | AP28: NY | AQ28: 053 | AR28: Madison County
A29: 36 | B29: METRO40380M40380 | C29: Rochester, NY HUD Metro FMR Area | D29: 103900 | E29: 36400 | F29: 41600 | G29: 46800 | H29: 51950 | I29: 56150 | J29: 60300 | K29: 64450 | L29: 68600 | M29: 43680 | N29: 49920 | O29: 56160 | P29: 62340 | Q29: 67380 | R29: 72360 | S29: 77340 | T29: 82320 | U29: Special | V29: 36750 | W29: 42000 | X29: 47250 | Y29: 52450 | Z29: 56650 | AA29: 60850 | AB29: 65050 | AC29: 69250 | AD29: 44100 | AE29: 50400 | AF29: 56700 | AG29: 62940 | AH29: 67980 | AI29: 73020 | AJ29: 78060 | AK29: 83100 | AL29: 36 | AM29: NEW YORK | AN29: 1 | AO29: Monroe County | AP29: NY | AQ29: 055 | AR29: Monroe County
A30: 36 | B30: NCNTY36057N36057 | C30: Montgomery County, NY | D30: 92900 | E30: 31950 | F30: 36450 | G30: 41050 | H30: 45600 | I30: 49250 | J30: 52900 | K30: 56550 | L30: 60200 | M30: 38340 | N30: 43740 | O30: 49260 | P30: 54720 | Q30: 59100 | R30: 63480 | S30: 67860 | T30: 72240 | U30: Special | V30: 40500 | W30: 46300 | X30: 52100 | Y30: 57850 | Z30: 62500 | AA30: 67150 | AB30: 71750 | AC30: 76400 | AD30: 48600 | AE30: 55560 | AF30: 62520 | AG30: 69420 | AH30: 75000 | AI30: 80580 | AJ30: 86100 | AK30: 91680 | AL30: 36 | AM30: NEW YORK | AN30: 0 | AO30: Montgomery County | AP30: NY | AQ30: 057 | AR30: Montgomery County
A31: 36 | B31: METRO35620MM5380 | C31: Nassau-Suffolk, NY HUD Metro FMR Area | D31: 164900 | E31: 57750 | F31: 66000 | G31: 74250 | H31: 82450 | I31: 89050 | J31: 95650 | K31: 102250 | L31: 108850 | M31: 69300 | N31: 79200 | O31: 89100 | P31: 98940 | Q31: 106860 | R31: 114780 | S31: 122700 | T31: 130620 | U31: Regular | AL31: 36 | AM31: NEW YORK | AN31: 1 | AO31: Nassau County | AP31: NY | AQ31: 059 | AR31: Nassau County
A32: 36 | B32: METRO35620MM5600 | C32: New York, NY HUD Metro FMR Area | D32: 103000 | E32: 56700 | F32: 64800 | G32: 72900 | H32: 81000 | I32: 87500 | J32: 94000 | K32: 100450 | L32: 106950 | M32: 68040 | N32: 77760 | O32: 87480 | P32: 97200 | Q32: 105000 | R32: 112800 | S32: 120540 | T32: 128340 | U32: Regular | AL32: 36 | AM32: NEW YORK | AN32: 1 | AO32: New York County | AP32: NY | AQ32: 061 | AR32: New York County
A33: 36 | B33: METRO15380M15380 | C33: Buffalo-Cheektowaga-Niagara Falls, NY MSA | D33: 101000 | E33: 35350 | F33: 40400 | G33: 45450 | H33: 50500 | I33: 54550 | J33: 58600 | K33: 62650 | L33: 66700 | M33: 42420 | N33: 48480 | O33: 54540 | P33: 60600 | Q33: 65460 | R33: 70320 | S33: 75180 | T33: 80040 | U33: Regular | AL33: 36 | AM33: NEW YORK | AN33: 1 | AO33: Niagara County | AP33: NY | AQ33: 063 | AR33: Niagara County
A34: 36 | B34: METRO46540M46540 | C34: Utica-Rome, NY MSA | D34: 89000 | E34: 31150 | F34: 35600 | G34: 40050 | H34: 44500 | I34: 48100 | J34: 51650 | K34: 55200 | L34: 58750 | M34: 37380 | N34: 42720 | O34: 48060 | P34: 53400 | Q34: 57720 | R34: 61980 | S34: 66240 | T34: 70500 | U34: Regular | AL34: 36 | AM34: NEW YORK | AN34: 1 | AO34: Oneida County | AP34: NY | AQ34: 065 | AR34: Oneida County
A35: 36 | B35: METRO45060M45060 | C35: Syracuse, NY MSA | D35: 104100 | E35: 36250 | F35: 41400 | G35: 46600 | H35: 51750 | I35: 55900 | J35: 60050 | K35: 64200 | L35: 68350 | M35: 43500 | N35: 49680 | O35: 55920 | P35: 62100 | Q35: 67080 | R35: 72060 | S35: 77040 | T35: 82020 | U35: Special | V35: 36450 | W35: 41650 | X35: 46850 | Y35: 52050 | Z35: 56250 | AA35: 60400 | AB35: 64550 | AC35: 68750 | AD35: 43740 | AE35: 49980 | AF35: 56220 | AG35: 62460 | AH35: 67500 | AI35: 72480 | AJ35: 77460 | AK35: 82500 | AL35: 36 | AM35: NEW YORK | AN35: 1 | AO35: Onondaga County | AP35: NY | AQ35: 067 | AR35: Onondaga County
A36: 36 | B36: METRO40380M40380 | C36: Rochester, NY HUD Metro FMR Area | D36: 103900 | E36: 36400 | F36: 41600 | G36: 46800 | H36: 51950 | I36: 56150 | J36: 60300 | K36: 64450 | L36: 68600 | M36: 43680 | N36: 49920 | O36: 56160 | P36: 62340 | Q36: 67380 | R36: 72360 | S36: 77340 | T36: 82320 | U36: Special | V36: 36750 | W36: 42000 | X36: 47250 | Y36: 52450 | Z36: 56650 | AA36: 60850 | AB36: 65050 | AC36: 69250 | AD36: 44100 | AE36: 50400 | AF36: 56700 | AG36: 62940 | AH36: 67980 | AI36: 73020 | AJ36: 78060 | AK36: 83100 | AL36: 36 | AM36: NEW YORK | AN36: 1 | AO36: Ontario County | AP36: NY | AQ36: 069 | AR36: Ontario County
A37: 36 | B37: METRO28880M28880 | C37: Kiryas Joel-Poughkeepsie-Newburgh, NY MSA | D37: 123000 | E37: 43050 | F37: 49200 | G37: 55350 | H37: 61500 | I37: 66450 | J37: 71350 | K37: 76300 | L37: 81200 | M37: 51660 | N37: 59040 | O37: 66420 | P37: 73800 | Q37: 79740 | R37: 85620 | S37: 91560 | T37: 97440 | U37: Regular | AL37: 36 | AM37: NEW YORK | AN37: 1 | AO37: Orange County | AP37: NY | AQ37: 071 | AR37: Orange County
A38: 36 | B38: METRO40380M40380 | C38: Rochester, NY HUD Metro FMR Area | D38: 103900 | E38: 36400 | F38: 41600 | G38: 46800 | H38: 51950 | I38: 56150 | J38: 60300 | K38: 64450 | L38: 68600 | M38: 43680 | N38: 49920 | O38: 56160 | P38: 62340 | Q38: 67380 | R38: 72360 | S38: 77340 | T38: 82320 | U38: Special | V38: 36750 | W38: 42000 | X38: 47250 | Y38: 52450 | Z38: 56650 | AA38: 60850 | AB38: 65050 | AC38: 69250 | AD38: 44100 | AE38: 50400 | AF38: 56700 | AG38: 62940 | AH38: 67980 | AI38: 73020 | AJ38: 78060 | AK38: 83100 | AL38: 36 | AM38: NEW YORK | AN38: 1 | AO38: Orleans County | AP38: NY | AQ38: 073 | AR38: Orleans County
A39: 36 | B39: METRO45060M45060 | C39: Syracuse, NY MSA | D39: 104100 | E39: 36250 | F39: 41400 | G39: 46600 | H39: 51750 | I39: 55900 | J39: 60050 | K39: 64200 | L39: 68350 | M39: 43500 | N39: 49680 | O39: 55920 | P39: 62100 | Q39: 67080 | R39: 72060 | S39: 77040 | T39: 82020 | U39: Special | V39: 36450 | W39: 41650 | X39: 46850 | Y39: 52050 | Z39: 56250 | AA39: 60400 | AB39: 64550 | AC39: 68750 | AD39: 43740 | AE39: 49980 | AF39: 56220 | AG39: 62460 | AH39: 67500 | AI39: 72480 | AJ39: 77460 | AK39: 82500 | AL39: 36 | AM39: NEW YORK | AN39: 1 | AO39: Oswego County | AP39: NY | AQ39: 075 | AR39: Oswego County
A40: 36 | B40: NCNTY36077N36077 | C40: Otsego County, NY | D40: 91200 | E40: 31950 | F40: 36500 | G40: 41050 | H40: 45600 | I40: 49250 | J40: 52900 | K40: 56550 | L40: 60200 | M40: 38340 | N40: 43800 | O40: 49260 | P40: 54720 | Q40: 59100 | R40: 63480 | S40: 67860 | T40: 72240 | U40: Regular | AL40: 36 | AM40: NEW YORK | AN40: 0 | AO40: Otsego County | AP40: NY | AQ40: 077 | AR40: Otsego County
...

Sheet Income Limits Table
B1: =CONCATENATE("AHC STATEWIDE AND AREA INCOME LIMITS FOR LOW INCOME FAMILIES, BY HUD LOW INCOME LIMIT PERCENTAGE AND NUMBER OF PERSONS, IN THE METROPOLITAN AREAS AND NON-METROPOLITAN COUNTIES OF NEW YORK STATE ",LEFT($C$2,4)) -> AHC STATEWIDE AND AREA INCOME LIMITS FOR LOW INCOME FAMILIES, BY HUD LOW INCOME LIMIT PERCENTAGE AND NUMBER OF PERSONS, IN THE METROPOLITAN AREAS AND NON-METROPOLITAN COUNTIES OF NEW YORK STATE 2025
B2: Area | C2: =CONCATENATE(RIGHT(NYMTSP!$D$1,4)," Median Income") -> 2025 Median Income | D2: 125% HLIL (100% AMI)
D3: 1 Person | E3: 2 Person | F3: 3 Person | G3: 4 Person | H3: 5 Person | I3: 6 Person | J3: 7 Person | K3: 8 Person
B4: NYS MEDIAN FAMILY INCOME | C4: 110200 | D4: Option | E4: Option | F4: Option | G4: Option | H4: Option | I4: Option | J4: Option | K4: Option
B5: NON-METROPOLITAN AREAS | C5: 82300 | D5: =$D$2 -> 125% HLIL (100% AMI) | E5: =$D$2 -> 125% HLIL (100% AMI) | F5: =$D$2 -> 125% HLIL (100% AMI) | G5: =$D$2 -> 125% HLIL (100% AMI) | H5: =$D$2 -> 125% HLIL (100% AMI) | I5: =$D$2 -> 125% HLIL (100% AMI) | J5: =$D$2 -> 125% HLIL (100% AMI) | K5: =$D$2 -> 125% HLIL (100% AMI)
B6: UNITED STATES | C6: 104200
A7: Albany-Schenectady-Troy, NY MSA | B7: =CONCATENATE(INDEX(NYMTSP!$AR:$AR,ROW()-5,1)," ",IF(AND($C7<$C$5,VLOOKUP($A7,NYMTSP!$C:$G,5,FALSE)=($C$5/2)),"*",IF($C7<(2*VLOOKUP($A7,NYMTSP!$C:$G,5,FALSE)),"#","")),IF(VLOOKUP($A7,NYMTSP!$C:$G,5,FALSE)>$C$6,"†","")) -> Albany County | C7: =VLOOKUP($A7,NYMTSP!$C:$L,2,FALSE) -> 116100 | D7: =ROUND(VLOOKUP($D$2,'Income Limits Definitions'!$A:$C,3,FALSE)*VLOOKUP($A7,NYMTSP!$C:$L,3,FALSE),-2) -> 81300 | E7: =ROUND(VLOOKUP($D$2,'Income Limits Definitions'!$A:$C,3,FALSE)*VLOOKUP($A7,NYMTSP!$C:$L,4,FALSE),-2) -> 92900 | F7: =ROUND(VLOOKUP($D$2,'Income Limits Definitions'!$A:$C,3,FALSE)*VLOOKUP($A7,NYMTSP!$C:$L,5,FALSE),-2) -> 104500 | G7: =ROUND(VLOOKUP($D$2,'Income Limits Definitions'!$A:$C,3,FALSE)*VLOOKUP($A7,NYMTSP!$C:$L,6,FALSE),-2) -> 116100 | H7: =ROUND(VLOOKUP($D$2,'Income Limits Definitions'!$A:$C,3,FALSE)*VLOOKUP($A7,NYMTSP!$C:$L,7,FALSE),-2) -> 125400 | I7: =ROUND(VLOOKUP($D$2,'Income Limits Definitions'!$A:$C,3,FALSE)*VLOOKUP($A7,NYMTSP!$C:$L,8,FALSE),-2) -> 134700 | J7: =ROUND(VLOOKUP($D$2,'Income Limits Definitions'!$A:$C,3,FALSE)*VLOOKUP($A7,NYMTSP!$C:$L,9,FALSE),-2) -> 144000 | K7: =ROUND(VLOOKUP($D$2,'Income Limits Definitions'!$A:$C,3,FALSE)*VLOOKUP($A7,NYMTSP!$C:$L,10,FALSE),-2) -> 153300
A8: Allegany County, NY | B8: =CONCATENATE(INDEX(NYMTSP!$AR:$AR,ROW()-5,1)," ",IF(AND($C8<$C$5,VLOOKUP($A8,NYMTSP!$C:$G,5,FALSE)=($C$5/2)),"*",IF($C8<(2*VLOOKUP($A8,NYMTSP!$C:$G,5,FALSE)),"#","")),IF(VLOOKUP($A8,NYMTSP!$C:$G,5,FALSE)>$C$6,"†","")) -> Allegany County | C8: =VLOOKUP($A8,NYMTSP!$C:$L,2,FALSE) -> 86400 | D8: =ROUND(VLOOKUP($D$2,'Income Limits Definitions'!$A:$C,3,FALSE)*VLOOKUP($A8,NYMTSP!$C:$L,3,FALSE),-2) -> 62000 | E8: =ROUND(VLOOKUP($D$2,'Income Limits Definitions'!$A:$C,3,FALSE)*VLOOKUP($A8,NYMTSP!$C:$L,4,FALSE),-2) -> 70800 | F8: =ROUND(VLOOKUP($D$2,'Income Limits Definitions'!$A:$C,3,FALSE)*VLOOKUP($A8,NYMTSP!$C:$L,5,FALSE),-2) -> 79700 | G8: =ROUND(VLOOKUP($D$2,'Income Limits Definitions'!$A:$C,3,FALSE)*VLOOKUP($A8,NYMTSP!$C:$L,6,FALSE),-2) -> 88500 | H8: =ROUND(VLOOKUP($D$2,'Income Limits Definitions'!$A:$C,3,FALSE)*VLOOKUP($A8,NYMTSP!$C:$L,7,FALSE),-2) -> 95600 | I8: =ROUND(VLOOKUP($D$2,'Income Limits Definitions'!$A:$C,3,FALSE)*VLOOKUP($A8,NYMTSP!$C:$L,8,FALSE),-2) -> 102700 | J8: =ROUND(VLOOKUP($D$2,'Income Limits Definitions'!$A:$C,3,FALSE)*VLOOKUP($A8,NYMTSP!$C:$L,9,FALSE),-2) -> 109800 | K8: =ROUND(VLOOKUP($D$2,'Income Limits Definitions'!$A:$C,3,FALSE)*VLOOKUP($A8,NYMTSP!$C:$L,10,FALSE),-2) -> 116900
A9: New York, NY HUD Metro FMR Area | B9: =CONCATENATE(INDEX(NYMTSP!$AR:$AR,ROW()-5,1)," ",IF(AND($C9<$C$5,VLOOKUP($A9,NYMTSP!$C:$G,5,FALSE)=($C$5/2)),"*",IF($C9<(2*VLOOKUP($A9,NYMTSP!$C:$G,5,FALSE)),"#","")),IF(VLOOKUP($A9,NYMTSP!$C:$G,5,FALSE)>$C$6,"†","")) -> Bronx County # | C9: =VLOOKUP($A9,NYMTSP!$C:$L,2,FALSE) -> 103000 | D9: =ROUND(VLOOKUP($D$2,'Income Limits Definitions'!$A:$C,3,FALSE)*VLOOKUP($A9,NYMTSP!$C:$L,3,FALSE),-2) -> 113400 | E9: =ROUND(VLOOKUP($D$2,'Income Limits Definitions'!$A:$C,3,FALSE)*VLOOKUP($A9,NYMTSP!$C:$L,4,FALSE),-2) -> 129600 | F9: =ROUND(VLOOKUP($D$2,'Income Limits Definitions'!$A:$C,3,FALSE)*VLOOKUP($A9,NYMTSP!$C:$L,5,FALSE),-2) -> 145800 | G9: =ROUND(VLOOKUP($D$2,'Income Limits Definitions'!$A:$C,3,FALSE)*VLOOKUP($A9,NYMTSP!$C:$L,6,FALSE),-2) -> 162000 | H9: =ROUND(VLOOKUP($D$2,'Income Limits Definitions'!$A:$C,3,FALSE)*VLOOKUP($A9,NYMTSP!$C:$L,7,FALSE),-2) -> 175000 | I9: =ROUND(VLOOKUP($D$2,'Income Limits Definitions'!$A:$C,3,FALSE)*VLOOKUP($A9,NYMTSP!$C:$L,8,FALSE),-2) -> 188000 | J9: =ROUND(VLOOKUP($D$2,'Income Limits Definitions'!$A:$C,3,FALSE)*VLOOKUP($A9,NYMTSP!$C:$L,9,FALSE),-2) -> 200900 | K9: =ROUND(VLOOKUP($D$2,'Income Limits Definitions'!$A:$C,3,FALSE)*VLOOKUP($A9,NYMTSP!$C:$L,10,FALSE),-2) -> 213900
A10: Binghamton, NY MSA | B10: =CONCATENATE(INDEX(NYMTSP!$AR:$AR,ROW()-5,1)," ",IF(AND($C10<$C$5,VLOOKUP($A10,NYMTSP!$C:$G,5,FALSE)=($C$5/2)),"*",IF($C10<(2*VLOOKUP($A10,NYMTSP!$C:$G,5,FALSE)),"#","")),IF(VLOOKUP($A10,NYMTSP!$C:$G,5,FALSE)>$C$6,"†","")) -> Broome County | C10: =VLOOKUP($A10,NYMTSP!$C:$L,2,FALSE) -> 94500 | D10: =ROUND(VLOOKUP($D$2,'Income Limits Definitions'!$A:$C,3,FALSE)*VLOOKUP($A10,NYMTSP!$C:$L,3,FALSE),-2) -> 66200 | E10: =ROUND(VLOOKUP($D$2,'Income Limits Definitions'!$A:$C,3,FALSE)*VLOOKUP($A10,NYMTSP!$C:$L,4,FALSE),-2) -> 75600 | F10: =ROUND(VLOOKUP($D$2,'Income Limits Definitions'!$A:$C,3,FALSE)*VLOOKUP($A10,NYMTSP!$C:$L,5,FALSE),-2) -> 85100 | G10: =ROUND(VLOOKUP($D$2,'Income Limits Definitions'!$A:$C,3,FALSE)*VLOOKUP($A10,NYMTSP!$C:$L,6,FALSE),-2) -> 94500 | H10: =ROUND(VLOOKUP($D$2,'Income Limits Definitions'!$A:$C,3,FALSE)*VLOOKUP($A10,NYMTSP!$C:$L,7,FALSE),-2) -> 102100 | I10: =ROUND(VLOOKUP($D$2,'Income Limits Definitions'!$A:$C,3,FALSE)*VLOOKUP($A10,NYMTSP!$C:$L,8,FALSE),-2) -> 109700 | J10: =ROUND(VLOOKUP($D$2,'Income Limits Definitions'!$A:$C,3,FALSE)*VLOOKUP($A10,NYMTSP!$C:$L,9,FALSE),-2) -> 117200 | K10: =ROUND(VLOOKUP($D$2,'Income Limits Definitions'!$A:$C,3,FALSE)*VLOOKUP($A10,NYMTSP!$C:$L,10,FALSE),-2) -> 124800
A11: Cattaraugus County, NY | B11: =CONCATENATE(INDEX(NYMTSP!$AR:$AR,ROW()-5,1)," ",IF(AND($C11<$C$5,VLOOKUP($A11,NYMTSP!$C:$G,5,FALSE)=($C$5/2)),"*",IF($C11<(2*VLOOKUP($A11,NYMTSP!$C:$G,5,FALSE)),"#","")),IF(VLOOKUP($A11,NYMTSP!$C:$G,5,FALSE)>$C$6,"†","")) -> Cattaraugus County # | C11: =VLOOKUP($A11,NYMTSP!$C:$L,2,FALSE) -> 77200 | D11: =ROUND(VLOOKUP($D$2,'Income Limits Definitions'!$A:$C,3,FALSE)*VLOOKUP($A11,NYMTSP!$C:$L,3,FALSE),-2) -> 62000 | E11: =ROUND(VLOOKUP($D$2,'Income Limits Definitions'!$A:$C,3,FALSE)*VLOOKUP($A11,NYMTSP!$C:$L,4,FALSE),-2) -> 70800 | F11: =ROUND(VLOOKUP($D$2,'Income Limits Definitions'!$A:$C,3,FALSE)*VLOOKUP($A11,NYMTSP!$C:$L,5,FALSE),-2) -> 79700 | G11: =ROUND(VLOOKUP($D$2,'Income Limits Definitions'!$A:$C,3,FALSE)*VLOOKUP($A11,NYMTSP!$C:$L,6,FALSE),-2) -> 88500 | H11: =ROUND(VLOOKUP($D$2,'Income Limits Definitions'!$A:$C,3,FALSE)*VLOOKUP($A11,NYMTSP!$C:$L,7,FALSE),-2) -> 95600 | I11: =ROUND(VLOOKUP($D$2,'Income Limits Definitions'!$A:$C,3,FALSE)*VLOOKUP($A11,NYMTSP!$C:$L,8,FALSE),-2) -> 102700 | J11: =ROUND(VLOOKUP($D$2,'Income Limits Definitions'!$A:$C,3,FALSE)*VLOOKUP($A11,NYMTSP!$C:$L,9,FALSE),-2) -> 109800 | K11: =ROUND(VLOOKUP($D$2,'Income Limits Definitions'!$A:$C,3,FALSE)*VLOOKUP($A11,NYMTSP!$C:$L,10,FALSE),-2) -> 116900
A12: Cayuga County, NY | B12: =CONCATENATE(INDEX(NYMTSP!$AR:$AR,ROW()-5,1)," ",IF(AND($C12<$C$5,VLOOKUP($A12,NYMTSP!$C:$G,5,FALSE)=($C$5/2)),"*",IF($C12<(2*VLOOKUP($A12,NYMTSP!$C:$G,5,FALSE)),"#","")),IF(VLOOKUP($A12,NYMTSP!$C:$G,5,FALSE)>$C$6,"†","")) -> Cayuga County | C12: =VLOOKUP($A12,NYMTSP!$C:$L,2,FALSE) -> 83500 | D12: =ROUND(VLOOKUP($D$2,'Income Limits Definitions'!$A:$C,3,FALSE)*VLOOKUP($A12,NYMTSP!$C:$L,3,FALSE),-2) -> 62000 | E12: =ROUND(VLOOKUP($D$2,'Income Limits Definitions'!$A:$C,3,FALSE)*VLOOKUP($A12,NYMTSP!$C:$L,4,FALSE),-2) -> 70800 | F12: =ROUND(VLOOKUP($D$2,'Income Limits Definitions'!$A:$C,3,FALSE)*VLOOKUP($A12,NYMTSP!$C:$L,5,FALSE),-2) -> 79700 | G12: =ROUND(VLOOKUP($D$2,'Income Limits Definitions'!$A:$C,3,FALSE)*VLOOKUP($A12,NYMTSP!$C:$L,6,FALSE),-2) -> 88500 | H12: =ROUND(VLOOKUP($D$2,'Income Limits Definitions'!$A:$C,3,FALSE)*VLOOKUP($A12,NYMTSP!$C:$L,7,FALSE),-2) -> 95600 | I12: =ROUND(VLOOKUP($D$2,'Income Limits Definitions'!$A:$C,3,FALSE)*VLOOKUP($A12,NYMTSP!$C:$L,8,FALSE),-2) -> 102700 | J12: =ROUND(VLOOKUP($D$2,'Income Limits Definitions'!$A:$C,3,FALSE)*VLOOKUP($A12,NYMTSP!$C:$L,9,FALSE),-2) -> 109800 | K12: =ROUND(VLOOKUP($D$2,'Income Limits Definitions'!$A:$C,3,FALSE)*VLOOKUP($A12,NYMTSP!$C:$L,10,FALSE),-2) -> 116900
A13: Chautauqua County, NY | B13: =CONCATENATE(INDEX(NYMTSP!$AR:$AR,ROW()-5,1)," ",IF(AND($C13<$C$5,VLOOKUP($A13,NYMTSP!$C:$G,5,FALSE)=($C$5/2)),"*",IF($C13<(2*VLOOKUP($A13,NYMTSP!$C:$G,5,FALSE)),"#","")),IF(VLOOKUP($A13,NYMTSP!$C:$G,5,FALSE)>$C$6,"†","")) -> Chautauqua County | C13: =VLOOKUP($A13,NYMTSP!$C:$L,2,FALSE) -> 82700 | D13: =ROUND(VLOOKUP($D$2,'Income Limits Definitions'!$A:$C,3,FALSE)*VLOOKUP($A13,NYMTSP!$C:$L,3,FALSE),-2) -> 62000 | E13: =ROUND(VLOOKUP($D$2,'Income Limits Definitions'!$A:$C,3,FALSE)*VLOOKUP($A13,NYMTSP!$C:$L,4,FALSE),-2) -> 70800 | F13: =ROUND(VLOOKUP($D$2,'Income Limits Definitions'!$A:$C,3,FALSE)*VLOOKUP($A13,NYMTSP!$C:$L,5,FALSE),-2) -> 79700 | G13: =ROUND(VLOOKUP($D$2,'Income Limits Definitions'!$A:$C,3,FALSE)*VLOOKUP($A13,NYMTSP!$C:$L,6,FALSE),-2) -> 88500 | H13: =ROUND(VLOOKUP($D$2,'Income Limits Definitions'!$A:$C,3,FALSE)*VLOOKUP($A13,NYMTSP!$C:$L,7,FALSE),-2) -> 95600 | I13: =ROUND(VLOOKUP($D$2,'Income Limits Definitions'!$A:$C,3,FALSE)*VLOOKUP($A13,NYMTSP!$C:$L,8,FALSE),-2) -> 102700 | J13: =ROUND(VLOOKUP($D$2,'Income Limits Definitions'!$A:$C,3,FALSE)*VLOOKUP($A13,NYMTSP!$C:$L,9,FALSE),-2) -> 109800 | K13: =ROUND(VLOOKUP($D$2,'Income Limits Definitions'!$A:$C,3,FALSE)*VLOOKUP($A13,NYMTSP!$C:$L,10,FALSE),-2) -> 116900
A14: Elmira, NY MSA | B14: =CONCATENATE(INDEX(NYMTSP!$AR:$AR,ROW()-5,1)," ",IF(AND($C14<$C$5,VLOOKUP($A14,NYMTSP!$C:$G,5,FALSE)=($C$5/2)),"*",IF($C14<(2*VLOOKUP($A14,NYMTSP!$C:$G,5,FALSE)),"#","")),IF(VLOOKUP($A14,NYMTSP!$C:$G,5,FALSE)>$C$6,"†","")) -> Chemung County | C14: =VLOOKUP($A14,NYMTSP!$C:$L,2,FALSE) -> 81900 | D14: =ROUND(VLOOKUP($D$2,'Income Limits Definitions'!$A:$C,3,FALSE)*VLOOKUP($A14,NYMTSP!$C:$L,3,FALSE),-2) -> 62000 | E14: =ROUND(VLOOKUP($D$2,'Income Limits Definitions'!$A:$C,3,FALSE)*VLOOKUP($A14,NYMTSP!$C:$L,4,FALSE),-2) -> 70800 | F14: =ROUND(VLOOKUP($D$2,'Income Limits Definitions'!$A:$C,3,FALSE)*VLOOKUP($A14,NYMTSP!$C:$L,5,FALSE),-2) -> 79700 | G14: =ROUND(VLOOKUP($D$2,'Income Limits Definitions'!$A:$C,3,FALSE)*VLOOKUP($A14,NYMTSP!$C:$L,6,FALSE),-2) -> 88500 | H14: =ROUND(VLOOKUP($D$2,'Income Limits Definitions'!$A:$C,3,FALSE)*VLOOKUP($A14,NYMTSP!$C:$L,7,FALSE),-2) -> 95600 | I14: =ROUND(VLOOKUP($D$2,'Income Limits Definitions'!$A:$C,3,FALSE)*VLOOKUP($A14,NYMTSP!$C:$L,8,FALSE),-2) -> 102700 | J14: =ROUND(VLOOKUP($D$2,'Income Limits Definitions'!$A:$C,3,FALSE)*VLOOKUP($A14,NYMTSP!$C:$L,9,FALSE),-2) -> 109800 | K14: =ROUND(VLOOKUP($D$2,'Income Limits Definitions'!$A:$C,3,FALSE)*VLOOKUP($A14,NYMTSP!$C:$L,10,FALSE),-2) -> 116900
A15: Chenango County, NY | B15: =CONCATENATE(INDEX(NYMTSP!$AR:$AR,ROW()-5,1)," ",IF(AND($C15<$C$5,VLOOKUP($A15,NYMTSP!$C:$G,5,FALSE)=($C$5/2)),"*",IF($C15<(2*VLOOKUP($A15,NYMTSP!$C:$G,5,FALSE)),"#","")),IF(VLOOKUP($A15,NYMTSP!$C:$G,5,FALSE)>$C$6,"†","")) -> Chenango County | C15: =VLOOKUP($A15,NYMTSP!$C:$L,2,FALSE) -> 83100 | D15: =ROUND(VLOOKUP($D$2,'Income Limits Definitions'!$A:$C,3,FALSE)*VLOOKUP($A15,NYMTSP!$C:$L,3,FALSE),-2) -> 62000 | E15: =ROUND(VLOOKUP($D$2,'Income Limits Definitions'!$A:$C,3,FALSE)*VLOOKUP($A15,NYMTSP!$C:$L,4,FALSE),-2) -> 70800 | F15: =ROUND(VLOOKUP($D$2,'Income Limits Definitions'!$A:$C,3,FALSE)*VLOOKUP($A15,NYMTSP!$C:$L,5,FALSE),-2) -> 79700 | G15: =ROUND(VLOOKUP($D$2,'Income Limits Definitions'!$A:$C,3,FALSE)*VLOOKUP($A15,NYMTSP!$C:$L,6,FALSE),-2) -> 88500 | H15: =ROUND(VLOOKUP($D$2,'Income Limits Definitions'!$A:$C,3,FALSE)*VLOOKUP($A15,NYMTSP!$C:$L,7,FALSE),-2) -> 95600 | I15: =ROUND(VLOOKUP($D$2,'Income Limits Definitions'!$A:$C,3,FALSE)*VLOOKUP($A15,NYMTSP!$C:$L,8,FALSE),-2) -> 102700 | J15: =ROUND(VLOOKUP($D$2,'Income Limits Definitions'!$A:$C,3,FALSE)*VLOOKUP($A15,NYMTSP!$C:$L,9,FALSE),-2) -> 109800 | K15: =ROUND(VLOOKUP($D$2,'Income Limits Definitions'!$A:$C,3,FALSE)*VLOOKUP($A15,NYMTSP!$C:$L,10,FALSE),-2) -> 116900
A16: Clinton County, NY | B16: =CONCATENATE(INDEX(NYMTSP!$AR:$AR,ROW()-5,1)," ",IF(AND($C16<$C$5,VLOOKUP($A16,NYMTSP!$C:$G,5,FALSE)=($C$5/2)),"*",IF($C16<(2*VLOOKUP($A16,NYMTSP!$C:$G,5,FALSE)),"#","")),IF(VLOOKUP($A16,NYMTSP!$C:$G,5,FALSE)>$C$6,"†","")) -> Clinton County | C16: =VLOOKUP($A16,NYMTSP!$C:$L,2,FALSE) -> 94300 | D16: =ROUND(VLOOKUP($D$2,'Income Limits Definitions'!$A:$C,3,FALSE)*VLOOKUP($A16,NYMTSP!$C:$L,3,FALSE),-2) -> 66100 | E16: =ROUND(VLOOKUP($D$2,'Income Limits Definitions'!$A:$C,3,FALSE)*VLOOKUP($A16,NYMTSP!$C:$L,4,FALSE),-2) -> 75500 | F16: =ROUND(VLOOKUP($D$2,'Income Limits Definitions'!$A:$C,3,FALSE)*VLOOKUP($A16,NYMTSP!$C:$L,5,FALSE),-2) -> 84900 | G16: =ROUND(VLOOKUP($D$2,'Income Limits Definitions'!$A:$C,3,FALSE)*VLOOKUP($A16,NYMTSP!$C:$L,6,FALSE),-2) -> 94300 | H16: =ROUND(VLOOKUP($D$2,'Income Limits Definitions'!$A:$C,3,FALSE)*VLOOKUP($A16,NYMTSP!$C:$L,7,FALSE),-2) -> 101900 | I16: =ROUND(VLOOKUP($D$2,'Income Limits Definitions'!$A:$C,3,FALSE)*VLOOKUP($A16,NYMTSP!$C:$L,8,FALSE),-2) -> 109400 | J16: =ROUND(VLOOKUP($D$2,'Income Limits Definitions'!$A:$C,3,FALSE)*VLOOKUP($A16,NYMTSP!$C:$L,9,FALSE),-2) -> 117000 | K16: =ROUND(VLOOKUP($D$2,'Income Limits Definitions'!$A:$C,3,FALSE)*VLOOKUP($A16,NYMTSP!$C:$L,10,FALSE),-2) -> 124500
A17: Columbia County, NY | B17: =CONCATENATE(INDEX(NYMTSP!$AR:$AR,ROW()-5,1)," ",IF(AND($C17<$C$5,VLOOKUP($A17,NYMTSP!$C:$G,5,FALSE)=($C$5/2)),"*",IF($C17<(2*VLOOKUP($A17,NYMTSP!$C:$G,5,FALSE)),"#","")),IF(VLOOKUP($A17,NYMTSP!$C:$G,5,FALSE)>$C$6,"†","")) -> Columbia County | C17: =VLOOKUP($A17,NYMTSP!$C:$L,2,FALSE) -> 113100 | D17: =ROUND(VLOOKUP($D$2,'Income Limits Definitions'!$A:$C,3,FALSE)*VLOOKUP($A17,NYMTSP!$C:$L,3,FALSE),-2) -> 78900 | E17: =ROUND(VLOOKUP($D$2,'Income Limits Definitions'!$A:$C,3,FALSE)*VLOOKUP($A17,NYMTSP!$C:$L,4,FALSE),-2) -> 90200 | F17: =ROUND(VLOOKUP($D$2,'Income Limits Definitions'!$A:$C,3,FALSE)*VLOOKUP($A17,NYMTSP!$C:$L,5,FALSE),-2) -> 101400 | G17: =ROUND(VLOOKUP($D$2,'Income Limits Definitions'!$A:$C,3,FALSE)*VLOOKUP($A17,NYMTSP!$C:$L,6,FALSE),-2) -> 112700 | H17: =ROUND(VLOOKUP($D$2,'Income Limits Definitions'!$A:$C,3,FALSE)*VLOOKUP($A17,NYMTSP!$C:$L,7,FALSE),-2) -> 121700 | I17: =ROUND(VLOOKUP($D$2,'Income Limits Definitions'!$A:$C,3,FALSE)*VLOOKUP($A17,NYMTSP!$C:$L,8,FALSE),-2) -> 130800 | J17: =ROUND(VLOOKUP($D$2,'Income Limits Definitions'!$A:$C,3,FALSE)*VLOOKUP($A17,NYMTSP!$C:$L,9,FALSE),-2) -> 139800 | K17: =ROUND(VLOOKUP($D$2,'Income Limits Definitions'!$A:$C,3,FALSE)*VLOOKUP($A17,NYMTSP!$C:$L,10,FALSE),-2) -> 148800
A18: Cortland County, NY | B18: =CONCATENATE(INDEX(NYMTSP!$AR:$AR,ROW()-5,1)," ",IF(AND($C18<$C$5,VLOOKUP($A18,NYMTSP!$C:$G,5,FALSE)=($C$5/2)),"*",IF($C18<(2*VLOOKUP($A18,NYMTSP!$C:$G,5,FALSE)),"#","")),IF(VLOOKUP($A18,NYMTSP!$C:$G,5,FALSE)>$C$6,"†","")) -> Cortland County | C18: =VLOOKUP($A18,NYMTSP!$C:$L,2,FALSE) -> 92200 | D18: =ROUND(VLOOKUP($D$2,'Income Limits Definitions'!$A:$C,3,FALSE)*VLOOKUP($A18,NYMTSP!$C:$L,3,FALSE),-2) -> 64600 | E18: =ROUND(VLOOKUP($D$2,'Income Limits Definitions'!$A:$C,3,FALSE)*VLOOKUP($A18,NYMTSP!$C:$L,4,FALSE),-2) -> 73800 | F18: =ROUND(VLOOKUP($D$2,'Income Limits Definitions'!$A:$C,3,FALSE)*VLOOKUP($A18,NYMTSP!$C:$L,5,FALSE),-2) -> 83000 | G18: =ROUND(VLOOKUP($D$2,'Income Limits Definitions'!$A:$C,3,FALSE)*VLOOKUP($A18,NYMTSP!$C:$L,6,FALSE),-2) -> 92200 | H18: =ROUND(VLOOKUP($D$2,'Income Limits Definitions'!$A:$C,3,FALSE)*VLOOKUP($A18,NYMTSP!$C:$L,7,FALSE),-2) -> 99600 | I18: =ROUND(VLOOKUP($D$2,'Income Limits Definitions'!$A:$C,3,FALSE)*VLOOKUP($A18,NYMTSP!$C:$L,8,FALSE),-2) -> 107000 | J18: =ROUND(VLOOKUP($D$2,'Income Limits Definitions'!$A:$C,3,FALSE)*VLOOKUP($A18,NYMTSP!$C:$L,9,FALSE),-2) -> 114400 | K18: =ROUND(VLOOKUP($D$2,'Income Limits Definitions'!$A:$C,3,FALSE)*VLOOKUP($A18,NYMTSP!$C:$L,10,FALSE),-2) -> 121800
... A68: Yates County, NY | B68: =CONCATENATE(INDEX(NYMTSP!$AR:$AR,ROW()-5,1)," ",IF(AND($C68<$C$5,VLOOKUP($A68,NYMTSP!$C:$G,5,FALSE)=($C$5/2)),"*",IF($C68<(2*VLOOKUP($A68,NYMTSP!$C:$G,5,FALSE)),"#","")),IF(VLOOKUP($A68,NYMTSP!$C:$G,5,FALSE)>$C$6,"†","")) -> Yates County | C68: =VLOOKUP($A68,NYMTSP!$C:$L,2,FALSE) -> 88800 | D68: =ROUND(VLOOKUP($D$2,'Income Limits Definitions'!$A:$C,3,FALSE)*VLOOKUP($A68,NYMTSP!$C:$L,3,FALSE),-2) -> 62200 | E68: =ROUND(VLOOKUP($D$2,'Income Limits Definitions'!$A:$C,3,FALSE)*VLOOKUP($A68,NYMTSP!$C:$L,4,FALSE),-2) -> 71100 | F68: =ROUND(VLOOKUP($D$2,'Income Limits Definitions'!$A:$C,3,FALSE)*VLOOKUP($A68,NYMTSP!$C:$L,5,FALSE),-2) -> 80000 | G68: =ROUND(VLOOKUP($D$2,'Income Limits Definitions'!$A:$C,3,FALSE)*VLOOKUP($A68,NYMTSP!$C:$L,6,FALSE),-2) -> 88800 | H68: =ROUND(VLOOKUP($D$2,'Income Limits Definitions'!$A:$C,3,FALSE)*VLOOKUP($A68,NYMTSP!$C:$L,7,FALSE),-2) -> 96000 | I68: =ROUND(VLOOKUP($D$2,'Income Limits Definitions'!$A:$C,3,FALSE)*VLOOKUP($A68,NYMTSP!$C:$L,8,FALSE),-2) -> 103100 | J68: =ROUND(VLOOKUP($D$2,'Income Limits Definitions'!$A:$C,3,FALSE)*VLOOKUP($A68,NYMTSP!$C:$L,9,FALSE),-2) -> 110200 | K68: =ROUND(VLOOKUP($D$2,'Income Limits Definitions'!$A:$C,3,FALSE)*VLOOKUP($A68,NYMTSP!$C:$L,10,FALSE),-2) -> 117300
B70: =CONCATENATE(RIGHT(NYMTSP!$D$1,4)," median incomes were issued by HUD, and are effective on, 4/1/",RIGHT(NYMTSP!$D$1,4),".") -> 2025 median incomes were issued by HUD, and are effective on, 4/1/2025.
B71: MSA: Metropolitan Statistical Area; PMSA: Primary Metropolitan Statistical Area.
B72: * - Low Income Limit adjusted upward to 80% of State Non-Metropolitan Area median income.
B73: † - HUD Low Income Limit is capped by US National Median Income, 160% of HUD Very Low Income Limit establishes AHC Low Income Limit
B74: # - Low Income Limit Adjusted Upward

Sheet Income Limits Definitions
A1: Approx. 38% HLIL (30% AMI) | B1: is equal to… | C1: =0.375*1.6 -> 0.6 | D1: HUD VLI | E1: HUD EXTREMELY LOW INCOME LIMIT | F1: 0.3 | G1: AMI
A2: Approx. 63% HLIL (50% AMI) | B2: is equal to… | C2: =0.625*1.6 -> 1 | D2: HUD VLI | E2: HUD VERY LOW INCOME LIMIT | F2: 0.5 | G2: AMI
A3: 75% HLIL (60% AMI) | B3: is equal to… | C3: =0.75*1.6 -> 1.2 | D3: HUD VLI | E3: 75% OF THE HUD LOW INCOME LIMIT | F3: 0.6 | G3: AMI
A4: 100% HLIL (80% AMI) | B4: is equal to… | C4: =1*1.6 -> 1.6 | D4: HUD VLI | E4: HUD LOW INCOME LIMIT | F4: =C4*0.5 -> 0.8 | G4: AMI
A5: 112% HLIL (approx. 90% AMI) | B5: is equal to… | C5: =1.12*1.6 -> 1.792 | D5: HUD VLI | E5: 112% OF THE HUD LOW INCOME LIMIT | F5: =C5*0.5 -> 0.896 | G5: AMI
A6: 120% HLIL (96% AMI) | B6: is equal to… | C6: =1.2*1.6 -> 1.92 | D6: HUD VLI | E6: 120% OF THE HUD LOW INCOME LIMIT | F6: =C6*0.5 -> 0.96 | G6: AMI
A7: 125% HLIL (100% AMI) | B7: is equal to… | C7: =1.25*1.6 -> 2 | D7: HUD VLI | E7: 125% OF THE HUD LOW INCOME LIMIT | F7: =C7*0.5 -> 1 | G7: AMI
A8: Approx. 156% HLIL (125% AMI) | B8: is equal to… | C8: =1.563*1.6 -> 2.5008 | D8: HUD VLI | E8: 156.3% OF THE HUD LOW INCOME LIMIT | F8: =C8*0.5 -> 1.2504 | G8: AMI
A9: 137% HLIL (approx. 110% AMI) | B9: is equal to… | C9: =1.37*1.6 -> 2.192 | D9: HUD VLI | E9: 137% OF THE HUD LOW INCOME LIMIT | F9: =C9*0.5 -> 1.096 | G9: AMI
A10: 144% HLIL (approx. 115% AMI) | B10: is equal to… | C10: =1.438*1.6 -> 2.3008 | D10: HUD VLI | E10: 144% OF THE HUD LOW INCOME LIMIT | F10: =C10*0.5 -> 1.1504 | G10: AMI
A11: 150% HLIL (120% AMI) | B11: is equal to… | C11: =1.5*1.6 -> 2.4 | D11: HUD VLI | E11: 150% OF THE HUD LOW INCOME LIMIT | F11: =C11*0.5 -> 1.2 | G11: AMI
A12: Approx. 163% HLIL (130% AMI) | B12: is equal to… | C12: =1.625*1.6 -> 2.6 | D12: HUD VLI | E12: 162.5% OF THE HUD LOW INCOME LIMIT | F12: =C12*0.5 -> 1.3 | G12: AMI
A13: 166% HLIL (approx. 133% AMI) | B13: is equal to… | C13: =1.66*1.6 -> 2.656 | D13: HUD VLI | E13: 166% OF THE HUD LOW INCOME LIMIT | F13: =C13*0.5 -> 1.328 | G13: AMI
