Workbook

Sheet HNY_CB1_filter
A1: Project ID | B1: Project Name | C1: Project Start Date | D1: Project Completion Date | E1: Building ID | F1: Number | G1: Street | H1: Borough | I1: Postcode | J1: BBL | K1: BIN | L1: Community Board | M1: Council District | N1: Census Tract | O1: NTA - Neighborhood Tabulation Area | P1: Latitude | Q1: Longitude | R1: Latitude (Internal) | S1: Longitude (Internal) | T1: Building Completion Date | U1: Reporting Construction Type | V1: Extended Affordability Only | W1: Prevailing Wage Status | X1: Extremely Low Income Units | Y1: Very Low Income Units | Z1: Low Income Units | AA1: Moderate Income Units | AB1: Middle Income Units | AC1: Other Income Units | AD1: Studio Units | AE1: 1-BR Units | AF1: 2-BR Units | AG1: 3-BR Units | AH1: 4-BR Units | AI1: 5-BR Units | AJ1: 6-BR+ Units | AK1: Unknown-BR Units | AL1: Counted Rental Units | AM1: Counted Homeownership Units | AN1: All Counted Units | AO1: Total Units
A2: 74488 | B2: MORNINGSIDE HEIGHTS III. HPO.FY25 | C2: 45838 | E2: 37512 | F2: 106 | G2: WEST 105 STREET | H2: Manhattan | I2: 10025 | J2: 1018590037 | K2: 1055923 | L2: MN-07 | M2: 7 | N2: 189 | O2: MN0703 | P2: 40.798689 | Q2: -73.963676 | R2: 40.798613 | S2: -73.964081 | U2: Preservation | V2: Yes | W2: Non Prevailing Wage | X2: 4 | Y2: 1 | Z2: 1 | AA2: 2 | AB2: 3 | AF2: 1 | AG2: 5 | AH2: 3 | AI2: 2 | AL2: 11 | AN2: 11 | AO2: 19
A3: 74488 | B3: MORNINGSIDE HEIGHTS III. HPO.FY25 | C3: 45838 | E3: 37594 | F3: 123 | G3: WEST 106 STREET | H3: Manhattan | I3: 10025 | J3: 1018610121 | K3: 1055982 | L3: MN-07 | M3: 7 | N3: 193 | O3: MN0703 | P3: 40.799634 | Q3: -73.963784 | R3: 40.799905 | S3: -73.963726 | U3: Preservation | V3: Yes | W3: Non Prevailing Wage | Y3: 1 | Z3: 1 | AA3: 3 | AB3: 5 | AF3: 3 | AG3: 4 | AH3: 3 | AL3: 10 | AN3: 10 | AO3: 10
A4: 74488 | B4: MORNINGSIDE HEIGHTS III. HPO.FY25 | C4: 45838 | E4: 37595 | F4: 125 | G4: WEST 106 STREET | H4: Manhattan | I4: 10025 | J4: 1018610021 | K4: 1055959 | L4: MN-07 | M4: 7 | N4: 193 | O4: MN0703 | P4: 40.799661 | Q4: -73.963849 | R4: 40.79993 | S4: -73.963787 | U4: Preservation | V4: Yes | W4: Non Prevailing Wage | Y4: 2 | Z4: 1 | AA4: 2 | AB4: 5 | AF4: 4 | AG4: 4 | AH4: 2 | AL4: 10 | AN4: 10 | AO4: 10
A5: 74488 | B5: MORNINGSIDE HEIGHTS III. HPO.FY25 | C5: 45838 | E5: 37596 | F5: 127 | G5: WEST 106 STREET | H5: Manhattan | I5: 10025 | J5: 1018610020 | K5: 1055958 | L5: MN-07 | M5: 7 | N5: 193 | O5: MN0703 | P5: 40.799688 | Q5: -73.96391 | R5: 40.799957 | S5: -73.963852 | U5: Preservation | V5: Yes | W5: Non Prevailing Wage | Y5: 1 | Z5: 2 | AA5: 1 | AB5: 6 | AF5: 5 | AG5: 2 | AH5: 3 | AL5: 10 | AN5: 10 | AO5: 10
A6: 74488 | B6: MORNINGSIDE HEIGHTS III. HPO.FY25 | C6: 45838 | E6: 37723 | F6: 203 | G6: WEST 108 STREET | H6: Manhattan | I6: 10025 | J6: 1018800027 | K6: 1056680 | L6: MN-07 | M6: 7 | N6: 195 | O6: MN0703 | P6: 40.801904 | Q6: -73.965123 | R6: 40.802165 | S6: -73.965177 | U6: Preservation | V6: Yes | W6: Non Prevailing Wage | X6: 7 | Y6: 2 | Z6: 1 | AA6: 2 | AB6: 6 | AC6: 1 | AD6: 1 | AF6: 3 | AG6: 12 | AH6: 3 | AL6: 19 | AN6: 19 | AO6: 21
A7: 76578 | B7: PUEBLO NUEVO.HUDMF.FY25 | C7: 45838 | D7: 45838 | E7: 805337 | F7: 210 | G7: STANTON STREET | H7: Manhattan | I7: 10002 | J7: 1003450048 | K7: 1004151 | L7: MN-03 | M7: 2 | N7: 2201 | O7: MN0302 | P7: 40.719598 | Q7: -73.982363 | R7: 40.720103 | S7: -73.982175 | T7: 45838 | U7: Preservation | V7: Yes | W7: Non Prevailing Wage | X7: 139 | Y7: 19 | Z7: 12 | AA7: 1 | AC7: 1 | AE7: 78 | AF7: 72 | AG7: 22 | AL7: 172 | AN7: 172 | AO7: 172
A8: 76639 | B8: WEST 104TH STREET.HUDMF.FY25 | C8: 45838 | E8: 25352 | F8: 82 | G8: MANHATTAN AVENUE | H8: Manhattan | I8: 10025 | J8: 1018390045 | K8: 1055483 | L8: MN-07 | M8: 7 | N8: 189 | O8: MN0703 | P8: 40.797056 | Q8: -73.96263 | R8: 40.797119 | S8: -73.962276 | U8: Preservation | V8: No | W8: Non Prevailing Wage | X8: 14 | Y8: 3 | Z8: 2 | AC8: 1 | AD8: 5 | AE8: 10 | AF8: 1 | AG8: 4 | AL8: 20 | AN8: 20 | AO8: 20
A9: 76639 | B9: WEST 104TH STREET.HUDMF.FY25 | C9: 45838 | E9: 37505 | F9: 73 | G9: WEST 104 STREET | H9: Manhattan | I9: 10025 | J9: 1018400005 | K9: 1055488 | L9: MN-07 | M9: 7 | N9: 189 | O9: MN0703 | P9: 40.797773 | Q9: -73.963474 | R9: 40.797841 | S9: -73.96303 | U9: Preservation | V9: No | W9: Non Prevailing Wage | X9: 29 | Y9: 5 | Z9: 5 | AE9: 14 | AF9: 5 | AG9: 15 | AH9: 5 | AL9: 39 | AN9: 39 | AO9: 39
A10: 74451 | B10: 45TH STREET HOUSING PARTNERS LLC.PLP.FY25 | C10: 45835 | E10: 33189 | F10: 357 | G10: WEST 45 STREET | H10: Manhattan | I10: 10036 | J10: 1010360005 | K10: 1085020 | L10: MN-04 | M10: 3 | N10: 12101 | O10: MN0402 | P10: 40.759826 | Q10: -73.989947 | R10: 40.760279 | S10: -73.990463 | U10: Preservation | V10: No | W10: Non Prevailing Wage | X10: 8 | Y10: 10 | Z10: 1 | AA10: 1 | AE10: 10 | AF10: 10 | AL10: 20 | AN10: 20 | AO10: 20
A11: 74451 | B11: 45TH STREET HOUSING PARTNERS LLC.PLP.FY25 | C11: 45835 | E11: 805624 | F11: 351 | G11: WEST 45 STREET | H11: Manhattan | I11: 10036 | J11: 1010360005 | K11: 1025006 | L11: MN-04 | M11: 3 | N11: 12101 | O11: MN0402 | P11: 40.759774 | Q11: -73.989828 | R11: 40.760279 | S11: -73.990463 | U11: Preservation | V11: No | W11: Non Prevailing Wage | X11: 9 | Y11: 9 | Z11: 1 | AA11: 1 | AE11: 10 | AF11: 10 | AL11: 20 | AN11: 20 | AO11: 20
A12: 74451 | B12: 45TH STREET HOUSING PARTNERS LLC.PLP.FY25 | C12: 45835 | E12: 805625 | F12: 353 | G12: WEST 45 STREET | H12: Manhattan | I12: 10036 | J12: 1010360005 | K12: 1085018 | L12: MN-04 | M12: 3 | N12: 12101 | O12: MN0402 | P12: 40.759791 | Q12: -73.989868 | R12: 40.760279 | S12: -73.990463 | U12: Preservation | V12: No | W12: Non Prevailing Wage | X12: 4 | Y12: 14 | Z12: 2 | AE12: 10 | AF12: 10 | AL12: 20 | AN12: 20 | AO12: 20
A13: 74451 | B13: 45TH STREET HOUSING PARTNERS LLC.PLP.FY25 | C13: 45835 | E13: 805626 | F13: 355 | G13: WEST 45 STREET | H13: Manhattan | I13: 10036 | J13: 1010360005 | K13: 1085019 | L13: MN-04 | M13: 3 | N13: 12101 | O13: MN0402 | P13: 40.75981 | Q13: -73.989907 | R13: 40.760279 | S13: -73.990463 | U13: Preservation | V13: No | W13: Non Prevailing Wage | X13: 9 | Y13: 8 | Z13: 1 | AA13: 2 | AE13: 10 | AF13: 10 | AL13: 20 | AN13: 20 | AO13: 20
A14: 74487 | B14: MORNINGSIDE HEIGHTS II.HPO.FY25 | C14: 45835 | E14: 6068 | F14: 929 | G14: AMSTERDAM AVENUE | H14: Manhattan | I14: 10025 | J14: 1018600064 | K14: 1055946 | L14: MN-07 | M14: 7 | N14: 189 | O14: MN0703 | P14: 40.80012 | Q14: -73.965933 | R14: 40.79998 | S14: -73.96564 | U14: Preservation | V14: Yes | W14: Non Prevailing Wage | X14: 2 | Y14: 2 | Z14: 1 | AA14: 4 | AB14: 4 | AF14: 6 | AG14: 7 | AL14: 13 | AN14: 13 | AO14: 13
A15: 74487 | B15: MORNINGSIDE HEIGHTS II.HPO.FY25 | C15: 45835 | E15: 6070 | F15: 931 | G15: AMSTERDAM AVENUE | H15: Manhattan | I15: 10025 | J15: 1018600063 | K15: 1055945 | L15: MN-07 | M15: 7 | N15: 189 | O15: MN0703 | P15: 40.800175 | Q15: -73.965893 | R15: 40.80004 | S15: -73.965597 | U15: Preservation | V15: Yes | W15: Non Prevailing Wage | X15: 3 | Y15: 1 | Z15: 1 | AA15: 6 | AB15: 2 | AF15: 3 | AG15: 10 | AL15: 13 | AN15: 13 | AO15: 13
A16: 74487 | B16: MORNINGSIDE HEIGHTS II.HPO.FY25 | C16: 45835 | E16: 6072 | F16: 933 | G16: AMSTERDAM AVENUE | H16: Manhattan | I16: 10025 | J16: 1018600061 | K16: 1055944 | L16: MN-07 | M16: 7 | N16: 189 | O16: MN0703 | P16: 40.800227 | Q16: -73.965853 | R16: 40.800131 | S16: -73.965528 | U16: Preservation | V16: Yes | W16: Non Prevailing Wage | X16: 1 | Y16: 7 | Z16: 8 | AA16: 6 | AB16: 3 | AE16: 14 | AF16: 6 | AG16: 5 | AL16: 25 | AN16: 25 | AO16: 28
A17: 74487 | B17: MORNINGSIDE HEIGHTS II.HPO.FY25 | C17: 45835 | E17: 6090 | F17: 965 | G17: AMSTERDAM AVENUE | H17: Manhattan | I17: 10025 | J17: 1018620003 | K17: 1055985 | L17: MN-07 | M17: 7 | N17: 193 | O17: MN0703 | P17: 40.8013 | Q17: -73.965065 | R17: 40.801237 | S17: -73.964726 | U17: Preservation | V17: Yes | W17: Non Prevailing Wage | X17: 5 | Y17: 5 | AA17: 9 | AB17: 7 | AF17: 14 | AG17: 12 | AL17: 26 | AN17: 26 | AO17: 28
A18: 74487 | B18: MORNINGSIDE HEIGHTS II.HPO.FY25 | C18: 45835 | E18: 6092 | F18: 969 | G18: AMSTERDAM AVENUE | H18: Manhattan | I18: 10025 | J18: 1018620064 | K18: 1055995 | L18: MN-07 | M18: 7 | N18: 193 | O18: MN0703 | P18: 40.801399 | Q18: -73.964993 | R18: 40.801327 | S18: -73.964657 | U18: Preservation | V18: Yes | W18: Non Prevailing Wage | X18: 1 | Y18: 2 | Z18: 1 | AA18: 3 | AB18: 5 | AF18: 7 | AG18: 5 | AL18: 12 | AN18: 12 | AO18: 12
A19: 74487 | B19: MORNINGSIDE HEIGHTS II.HPO.FY25 | C19: 45835 | E19: 6093 | F19: 971 | G19: AMSTERDAM AVENUE | H19: Manhattan | I19: 10025 | J19: 1018620063 | K19: 1055994 | L19: MN-07 | M19: 7 | N19: 193 | O19: MN0703 | P19: 40.801445 | Q19: -73.96496 | R19: 40.801393 | S19: -73.964625 | U19: Preservation | V19: Yes | W19: Non Prevailing Wage | X19: 1 | Y19: 1 | Z19: 1 | AA19: 4 | AC19: 1 | AF19: 1 | AG19: 6 | AH19: 1 | AL19: 8 | AN19: 8 | AO19: 9
A20: 74487 | B20: MORNINGSIDE HEIGHTS II.HPO.FY25 | C20: 45835 | E20: 25200 | F20: 165 | G20: MANHATTAN AVENUE | H20: Manhattan | I20: 10025 | J20: 1018430017 | K20: 1055686 | L20: MN-07 | M20: 7 | N20: 193 | O20: MN0703 | P20: 40.799616 | Q20: -73.96079 | R20: 40.799858 | S20: -73.960967 | U20: Preservation | V20: Yes | W20: Non Prevailing Wage | Y20: 6 | Z20: 1 | AB20: 15 | AE20: 10 | AF20: 12 | AL20: 22 | AN20: 22 | AO20: 23
A21: 74487 | B21: MORNINGSIDE HEIGHTS II.HPO.FY25 | C21: 45835 | E21: 37515 | F21: 120 | G21: WEST 105 STREET | H21: Manhattan | I21: 10025 | J21: 1018590039 | K21: 1055924 | L21: MN-07 | M21: 7 | N21: 189 | O21: MN0703 | P21: 40.798821 | Q21: -73.96399 | R21: 40.798755 | S21: -73.96437 | U21: Preservation | V21: Yes | W21: Non Prevailing Wage | X21: 1 | Y21: 22 | Z21: 1 | AA21: 9 | AB21: 20 | AE21: 13 | AF21: 27 | AG21: 11 | AH21: 2 | AL21: 53 | AN21: 53 | AO21: 62
A22: 74487 | B22: MORNINGSIDE HEIGHTS II.HPO.FY25 | C22: 45835 | E22: 944847 | F22: 169 | G22: MANHATTAN AVENUE | H22: Manhattan | I22: 10025 | J22: 1018430051 | K22: 1055699 | L22: MN-07 | M22: 7 | N22: 193 | O22: MN0703 | P22: 40.799679 | Q22: -73.960743 | R22: 40.799959 | S22: -73.960894 | U22: Preservation | V22: Yes | W22: Non Prevailing Wage | Y22: 2 | AA22: 10 | AB22: 10 | AE22: 7 | AF22: 5 | AG22: 10 | AL22: 22 | AN22: 22 | AO22: 26
A23: 74974 | B23: MASARYK TOWERS.HRP.FY25 | C23: 45834 | E23: 9707 | F23: 51 | G23: COLUMBIA STREET | H23: Manhattan | I23: 10002 | J23: 1003330001 | K23: 1082667 | L23: MN-03 | M23: 2 | N23: 2201 | O23: MN0302 | P23: 40.716686 | Q23: -73.980463 | R23: 40.717885 | S23: -73.980845 | U23: Preservation | V23: No | W23: Non Prevailing Wage | X23: 1 | Y23: 218 | AD23: 20 | AE23: 40 | AF23: 139 | AG23: 20 | AM23: 219 | AN23: 219 | AO23: 219
A24: 74974 | B24: MASARYK TOWERS.HRP.FY25 | C24: 45834 | E24: 804199 | F24: 71 | G24: COLUMBIA STREET | H24: Manhattan | I24: 10002 | J24: 1003330001 | K24: 1082665 | L24: MN-03 | M24: 2 | N24: 2201 | O24: MN0302 | P24: 40.717218 | Q24: -73.980174 | R24: 40.717885 | S24: -73.980845 | U24: Preservation | V24: No | W24: Non Prevailing Wage | Y24: 208 | AD24: 1 | AE24: 20 | AF24: 145 | AG24: 42 | AM24: 208 | AN24: 208 | AO24: 208
A25: 74974 | B25: MASARYK TOWERS.HRP.FY25 | C25: 45834 | E25: 804200 | F25: 75 | G25: COLUMBIA STREET | H25: Manhattan | I25: 10002 | J25: 1003330001 | K25: 1082666 | L25: MN-03 | M25: 2 | N25: 2201 | O25: MN0302 | P25: 40.717567 | Q25: -73.979986 | R25: 40.717885 | S25: -73.980845 | U25: Preservation | V25: No | W25: Non Prevailing Wage | Y25: 350 | AD25: 20 | AE25: 81 | AF25: 186 | AG25: 63 | AM25: 350 | AN25: 350 | AO25: 350
A26: 74974 | B26: MASARYK TOWERS.HRP.FY25 | C26: 45834 | E26: 804201 | F26: 85 | G26: COLUMBIA STREET | H26: Manhattan | I26: 10002 | J26: 1003330001 | K26: 1086089 | L26: MN-03 | M26: 2 | N26: 2201 | O26: MN0302 | P26: 40.717891 | Q26: -73.979824 | R26: 40.717885 | S26: -73.980845 | U26: Preservation | V26: No | W26: Non Prevailing Wage | Y26: 331 | AC26: 1 | AD26: 1 | AE26: 60 | AF26: 187 | AG26: 84 | AM26: 332 | AN26: 332 | AO26: 332
A27: 73351 | B27: TMN302G 1772 SECOND AVENUE - PASSAGEWAY WORK | C27: 45833 | E27: 1067 | F27: 1772 | G27: 2 AVENUE | H27: Manhattan | I27: 10128 | J27: 1015550004 | K27: 1050240 | L27: MN-08 | M27: 5 | N27: 15402 | O27: MN0803 | P27: 40.7819 | Q27: -73.948798 | R27: 40.781839 | S27: -73.94844 | U27: Preservation | V27: No | W27: Non Prevailing Wage | X27: 13 | AE27: 9 | AF27: 4 | AL27: 13 | AN27: 13 | AO27: 13
A28: 77126 | B28: 205 CABRINI BLVD APARTMENTS | C28: 45827 | E28: 8787 | F28: 201 | G28: CABRINI BOULEVARD | H28: Manhattan | I28: 10033 | J28: 1021790152 | K28: 1000000 | L28: MN-12 | M28: 10 | N28: 273 | O28: MN1202 | P28: 40.854257 | Q28: -73.938953 | R28: 40.854202 | S28: -73.9387 | U28: New Construction | V28: No | W28: Non Prevailing Wage | AB28: 7 | AE28: 1 | AF28: 6 | AL28: 7 | AN28: 7 | AO28: 21
A29: 75525 | B29: GRAND ST. GUILD. 145 BROOME ST | C29: 45826 | E29: 1013038 | F29: 145 | G29: BROOME STREET | H29: Manhattan | I29: 10002 | J29: 1003410062 | K29: 1000000 | L29: MN-03 | M29: 1 | N29: 1402 | O29: MN0302 | P29: 40.716401 | Q29: -73.984582 | R29: 40.716231 | S29: -73.98504 | U29: New Construction | V29: No | W29: Prevailing Wage | X29: 190 | AC29: 1 | AD29: 87 | AE29: 103 | AF29: 1 | AL29: 191 | AN29: 191 | AO29: 191
A30: 75177 | B30: 170 EAST 83RD STREET.HPO.FY25 | C30: 45813 | E30: 1781 | F30: 170 | G30: EAST 83 STREET | H30: Manhattan | I30: 10028 | J30: 1015110033 | K30: 1047619 | L30: MN-08 | M30: 4 | N30: 140 | O30: MN0802 | P30: 40.777182 | Q30: -73.956174 | R30: 40.776847 | S30: -73.955936 | U30: Preservation | V30: No | W30: Non Prevailing Wage | X30: 1 | Y30: 2 | Z30: 12 | AA30: 21 | AB30: 5 | AC30: 9 | AD30: 11 | AE30: 12 | AF30: 14 | AG30: 13 | AL30: 50 | AN30: 50 | AO30: 50
A31: 75539 | B31: MCKENNA SQUARE APARTMENTS.HUDMF.FY25 | C31: 45807 | E31: 5774 | F31: 2101 | G31: AMSTERDAM AVENUE | H31: Manhattan | I31: 10032 | J31: 1021110001 | K31: 1079860 | L31: MN-12 | M31: 10 | N31: 24301 | O31: MN1201 | P31: 40.83733 | Q31: -73.938752 | R31: 40.837258 | S31: -73.938416 | U31: Preservation | V31: No | W31: Non Prevailing Wage | X31: 23 | Y31: 3 | Z31: 3 | AE31: 14 | AF31: 9 | AG31: 6 | AL31: 29 | AN31: 29 | AO31: 29
A32: 75539 | B32: MCKENNA SQUARE APARTMENTS.HUDMF.FY25 | C32: 45807 | E32: 6174 | F32: 11 | G32: AUDUBON AVENUE | H32: Manhattan | I32: 10032 | J32: 1021230030 | K32: 1079869 | L32: MN-12 | M32: 10 | N32: 251 | O32: MN1201 | P32: 40.839051 | Q32: -73.939383 | R32: 40.838991 | S32: -73.939097 | U32: Preservation | V32: No | W32: Non Prevailing Wage | X32: 31 | Y32: 2 | Z32: 3 | AD32: 1 | AE32: 23 | AF32: 1 | AG32: 11 | AL32: 36 | AN32: 36 | AO32: 36
A33: 75539 | B33: MCKENNA SQUARE APARTMENTS.HUDMF.FY25 | C33: 45807 | E33: 804009 | F33: 2134 | G33: AMSTERDAM AVENUE | H33: Manhattan | I33: 10032 | J33: 1021230038 | K33: 1079873 | L33: MN-12 | M33: 10 | N33: 251 | O33: MN1201 | P33: 40.838408 | Q33: -73.937992 | R33: 40.838589 | S33: -73.938299 | U33: Preservation | V33: No | W33: Non Prevailing Wage | X33: 31 | Y33: 4 | Z33: 2 | AA33: 1 | AC33: 1 | AD33: 5 | AE33: 10 | AF33: 19 | AG33: 5 | AL33: 39 | AN33: 39 | AO33: 39
A34: 76950 | B34: CONFIDENTIAL | C34: 45807 | D34: 45807 | F34: ---- | G34: ---- | H34: Manhattan | L34: MN-08 | M34: 5 | T34: 45807 | U34: New Construction | V34: No | W34: Non Prevailing Wage | Z34: 1 | AE34: 1 | AM34: 1 | AN34: 1 | AO34: 1
A35: 77109 | B35: 217 WEST 123RD STREET APARTMENTS | C35: 45803 | E35: 1017361 | F35: 217 | G35: WEST 123 STREET | H35: Manhattan | I35: 10027 | J35: 1019290023 | K35: 1058625 | L35: MN-10 | M35: 9 | N35: 222 | O35: MN1001 | P35: 40.808014 | Q35: -73.950078 | R35: 40.808239 | S35: -73.950052 | U35: New Construction | V35: No | W35: Non Prevailing Wage | AB35: 9 | AD35: 7 | AE35: 1 | AF35: 1 | AL35: 9 | AN35: 9 | AO35: 27
A36: 76205 | B36: 180 EAST 125TH STREET | C36: 45797 | E36: 1017430 | F36: 180 | G36: EAST 125 STREET | H36: Manhattan | I36: 10035 | J36: 1017730027 | K36: 1000000 | L36: MN-11 | M36: 8 | N36: 196 | O36: MN1102 | P36: 40.803942 | Q36: -73.936413 | R36: 40.803602 | S36: -73.936634 | U36: New Construction | V36: No | W36: Non Prevailing Wage | Z36: 85 | AD36: 29 | AE36: 40 | AF36: 16 | AL36: 85 | AN36: 85 | AO36: 614
A37: 76892 | B37: CONFIDENTIAL | C37: 45786 | D37: 45786 | F37: ---- | G37: ---- | H37: Manhattan | L37: MN-12 | M37: 10 | T37: 45786 | U37: New Construction | V37: No | W37: Non Prevailing Wage | Y37: 1 | AE37: 1 | AM37: 1 | AN37: 1 | AO37: 1
A38: 77172 | B38: WESTBETH | C38: 45778 | E38: 44252 | F38: 445 | G38: WEST STREET | H38: Manhattan | I38: 10014 | J38: 1006390001 | K38: 1012047 | L38: MN-02 | M38: 3 | N38: 79 | O38: MN0203 | P38: 40.736109 | Q38: -74.010013 | R38: 40.736529 | S38: -74.009075 | U38: Preservation | V38: No | W38: Non Prevailing Wage | Z38: 384 | AC38: 1 | AD38: 258 | AE38: 85 | AF38: 3 | AG38: 37 | AK38: 2 | AL38: 385 | AN38: 385 | AO38: 385
A39: 76819 | B39: CONFIDENTIAL | C39: 45765 | D39: 45765 | F39: ---- | G39: ---- | H39: Manhattan | L39: MN-06 | M39: 4 | T39: 45765 | U39: New Construction | V39: No | W39: Non Prevailing Wage | Z39: 1 | AD39: 1 | AM39: 1 | AN39: 1 | AO39: 1
A40: 77118 | B40: 1440 AMSTERDAM AVENUE | C40: 45762 | E40: 5561 | F40: 1440 | G40: AMSTERDAM AVENUE | H40: Manhattan | I40: 10027 | J40: 1019840028 | K40: 1091802 | L40: MN-09 | M40: 7 | N40: 219 | O40: MN0902 | P40: 40.81671 | Q40: -73.953847 | R40: 40.816771 | S40: -73.954251 | U40: New Construction | V40: No | W40: Non Prevailing Wage | AB40: 147 | AD40: 20 | AE40: 66 | AF40: 61 | AL40: 147 | AN40: 147 | AO40: 490
...

Sheet HNY_CB1_raw1
A1: Project Name | B1: Borough | C1: Community Board | D1: Extremely Low Income Units | E1: Very Low Income Units | F1: Low Income Units | G1: Moderate Income Units | H1: Middle Income Units | I1: Other Income Units | J1: Total Units
A2: 55 BROAD STREET | B2: Manhattan | C2: MN-01 | E2: 29 | F2: 76 | G2: 38 | J2: =SUM(D2:I2) -> 143
A3: 25 WATER STREET | B3: Manhattan | C3: MN-01 | E3: 66 | F3: 4 | G3: 260 | J3: =SUM(D3:I3) -> 330
A4: 7 DEY STREET | B4: Manhattan | C4: MN-01 | F4: 21 | H4: 42 | J4: =SUM(D4:I4) -> 63
A5: EVERLASTING PINES HDFC | B5: Manhattan | C5: MN-01 | D5: 86 | E5: 1 | I5: 1 | J5: =SUM(D5:I5) -> 88
A6: 118 Fulton Street | B6: Manhattan | C6: MN-01 | F6: 97 | J6: =SUM(D6:I6) -> 97
A7: 56 FULTON STREET | B7: Manhattan | C7: MN-01 | E7: 12 | F7: 12 | H7: 6 | J7: =SUM(D7:I7) -> 30
A8: 456 Washington Street | B8: Manhattan | C8: MN-01 | F8: 22
E15: Extremely Low = 30% AMI
E17: Very Low = 40% AMI
E19: Low = 60% AMI
E21: Moderate = 80% AMI
E23: Middle = 120% AMI

Sheet SUMMARY - FINAL 
A1: Area Median Income (AMI)
A2: Family Size | B2: 0.3 | C2: 0.4 | D2: 0.5 | E2: 0.6 | F2: 0.7 | G2: 0.8 | H2: 0.9 | I2: 1 | J2: 1.1 | K2: 1.2 | L2: 1.3 | M2: 1.65 | Q2: AMI_Level | R2: Required_Income_3Person | S2: Units_Built
A3: 1 | B3: 34020 | C3: 45360 | D3: 56700 | E3: 68040 | F3: 79380 | G3: 90720 | H3: 102060 | I3: 113400 | J3: 124740 | K3: 136080 | L3: 147420 | M3: 187110
A4: 2 | B4: 38880 | C4: 51840 | D4: 64800 | E4: 77760 | F4: 90720 | G4: 103680 | H4: 116640 | I4: 129600 | J4: 142560 | K4: 155520 | L4: 168480 | M4: 213840
A5: Required Income 3 Person | B5: 43740 | C5: 58320 | D5: 72900 | E5: 87480 | F5: 102060 | G5: 116640 | H5: 131220 | I5: 145800 | J5: 160380 | K5: 174960 | L5: 189540 | M5: 240570 | P5: Extremely Low-Income | Q5: 0-30% | S5: 86
A6: Units Built | B6: =Summary!B2 -> 86 | D6: =Summary!B3 -> 108 | G6: =Summary!B4 -> 232 | K6: =Summary!B5 -> 298 | M6: =Summary!B6 -> 48 | P6: Very Low-Income | Q6: 31-50% | S6: 108
P7: Low-Income | Q7: 51-80% | S7: 232
P8: Moderate-Income | Q8: 81-120% | S8: 298
A9: Income Band | B9: Percent of AMI | P9: Middle-Income | Q9: 121-165% | S9: 48
A10: Extremely Low-Income | B10: 0-30%
A11: Very Low-Income | B11: 31-50%
A12: Low-Income | B12: 51-80%
A13: Moderate-Income | B13: 81-120%
A14: Middle-Income | B14: 121-165%
A17: Sources:
A18: Area Median Income - HPD
A19: Affordable Housing Production by Project | NYC Open Data

Sheet CB_income
A1: Community_Board | B1: Median_Household_income
A2: 101 | B2: 198945

Sheet AMI_referenc xe
A1: AMI_Level | B1: Required_Income_1_Person | C1: Required_Income_2_Person | D1: Required_Income_3_Person | E1: Required_Income_4_Person
A2: 0.3 | B2: $34,020 | C2: 38880 | D2: $43,740 | E2: 48600
A3: 0.4 | B3: 45360 | C3: $51,840 | D3: 58320 | E3: 64800
A4: 0.5 | B4: 56700 | C4: $64,800 | D4: 72900 | E4: 81000
A5: 0.6 | B5: $68,040 | C5: 77760 | D5: 87480 | E5: 97200
A6: 0.7 | B6: 79380 | C6: $90,720 | D6: $102,060 | E6: 113400
A7: 0.8 | B7: 90720 | C7: 103680 | D7: 116640 | E7: $129,600
A8: 0.9 | B8: $102,060 | C8: 116640 | D8: 131220 | E8: 145800
A9: 1 | B9: 113400 | C9: $129,600 | D9: 145800 | E9: 162000
A10: 1.1 | B10: 124740 | C10: 142560 | D10: 160380 | E10: 178200
A11: 1.2 | B11: 136080 | C11: 155520 | D11: 174960 | E11: 194400
A12: 1.3
A13: 1.65

Sheet AMI_reference 
A1: AMI_Level | B1: Required_Income_1_Person | C1: Required_Income_2_Person | D1: Required_Income_3_Person | E1: Required_Income_4_Person
A2: 0.3 | B2: 34020 | C2: 38880 | D2: 43740 | E2: 48600
A3: 0.4 | B3: 45360 | C3: 51840 | D3: 58320 | E3: 64800 | G3: read definitions
A4: 0.6 | B4: 68040 | C4: 77760 | D4: 87480 | E4: 97200
A5: 0.8 | B5: 90720 | C5: 103680 | D5: 116640 | E5: 129600
A6: 1.2 | B6: 136080 | C6: 155520 | D6: 174960 | E6: 194400

Sheet Summary
A1: AMI_Level | B1: Total_Units | C1: Median_Income | D1: Req_Income_1 | E1: Req_Income_2 | F1: Req_Income_3 | G1: Req_Income_4 | H1: Gap_1 | I1: Gap_2 | J1: Gap_3 | K1: Gap_4 | L1: HPD_Affordable_2BR_Rent_AMI | M1: CB1_Affordable_Rent_30pct | N1: GAP
A2: 0.3 | B2: =SUM(HNY_CB1_raw1!D2:D8) -> 86 | C2: =VLOOKUP(101, CB_income!$A$2:$B$2, 2, FALSE) -> 198945 | D2: =VLOOKUP(A2,AMI_reference!$A$2:$E$7, 2, FALSE) -> 34020 | E2: =VLOOKUP(A2,AMI_reference!$A$2:$E$7, 3, FALSE) -> 38880 | F2: =VLOOKUP(A2, AMI_reference!$A$2:$E$7, 4, FALSE) -> 43740 | G2: =VLOOKUP(A2,AMI_reference!$A$2:$E$7, 5, FALSE) -> 48600 | H2: =C2-D2 -> 164925 | I2: =C2-E2 -> 160065 | J2: =C2-F2 -> 155205 | K2: =C2-G2 -> 150345 | L2: =VLOOKUP(A2,AMI_rent_2BR!$A$2:$B$13,2,FALSE) -> 1093 | M2: =C2*0.3/12 -> 4973.625 | N2: =M2-L2 -> 3880.625
A3: 0.4 | B3: =SUM(HNY_CB1_raw1!E2:E7) -> 108 | C3: =VLOOKUP(101, CB_income!$A$2:$B$2, 2, FALSE) -> 198945 | D3: =VLOOKUP(A3,AMI_reference!$A$2:$E$7, 2, FALSE) -> 45360 | E3: =VLOOKUP(A3,AMI_reference!$A$2:$E$7, 3, FALSE) -> 51840 | F3: =VLOOKUP(A3, AMI_reference!$A$2:$E$7, 4, FALSE) -> 58320 | G3: =VLOOKUP(A3,AMI_reference!$A$2:$E$7, 5, FALSE) -> 64800 | H3: =C3-D3 -> 153585 | I3: =C3-E3 -> 147105 | J3: =C3-F3 -> 140625 | K3: =C3-G3 -> 134145 | L3: =VLOOKUP(A3,AMI_rent_2BR!$A$2:$B$13,2,FALSE) -> 1458 | M3: =C3*A3/12 -> 6631.5 | N3: =M3-L3 -> 5173.5
A4: 0.6 | B4: =SUM(HNY_CB1_raw1!F2:F8) -> 232 | C4: =VLOOKUP(101, CB_income!$A$2:$B$2, 2, FALSE) -> 198945 | D4: =VLOOKUP(A4,AMI_reference!$A$2:$E$7, 2, FALSE) -> 68040 | E4: =VLOOKUP(A4,AMI_reference!$A$2:$E$7, 3, FALSE) -> 77760 | F4: =VLOOKUP(A4, AMI_reference!$A$2:$E$7, 4, FALSE) -> 87480 | G4: =VLOOKUP(A4,AMI_reference!$A$2:$E$7, 5, FALSE) -> 97200 | H4: =C4-D4 -> 130905 | I4: =C4-E4 -> 121185 | J4: =C4-F4 -> 111465 | K4: =C4-G4 -> 101745 | L4: =VLOOKUP(A4,AMI_rent_2BR!$A$2:$B$13,2,FALSE) -> 2187 | M4: =C4*A4/12 -> 9947.25 | N4: =M4-L4 -> 7760.25
A5: 0.8 | B5: =SUM(HNY_CB1_raw1!G2:G8) -> 298 | C5: =VLOOKUP(101, CB_income!$A$2:$B$2, 2, FALSE) -> 198945 | D5: =VLOOKUP(A5,AMI_reference!$A$2:$E$7, 2, FALSE) -> 90720 | E5: =VLOOKUP(A5,AMI_reference!$A$2:$E$7, 3, FALSE) -> 103680 | F5: =VLOOKUP(A5, AMI_reference!$A$2:$E$7, 4, FALSE) -> 116640 | G5: =VLOOKUP(A5,AMI_reference!$A$2:$E$7, 5, FALSE) -> 129600 | H5: =C5-D5 -> 108225 | I5: =C5-E5 -> 95265 | J5: =C5-F5 -> 82305 | K5: =C5-G5 -> 69345 | L5: =VLOOKUP(A5,AMI_rent_2BR!$A$2:$B$13,2,FALSE) -> 2916 | M5: =C5*A5/12 -> 13263 | N5: =M5-L5 -> 10347
A6: 1.2 | B6: =SUM(HNY_CB1_raw1!H2:H8) -> 48 | C6: =VLOOKUP(101, CB_income!$A$2:$B$2, 2, FALSE) -> 198945 | D6: =VLOOKUP(A6,AMI_reference!$A$2:$E$7, 2, FALSE) -> 136080 | E6: =VLOOKUP(A6,AMI_reference!$A$2:$E$7, 3, FALSE) -> 155520 | F6: =VLOOKUP(A6, AMI_reference!$A$2:$E$7, 4, FALSE) -> 174960 | G6: =VLOOKUP(A6,AMI_reference!$A$2:$E$7, 5, FALSE) -> 194400 | H6: =C6-D6 -> 62865 | I6: =C6-E6 -> 43425 | J6: =C6-F6 -> 23985 | K6: =C6-G6 -> 4545 | L6: =VLOOKUP(A6,AMI_rent_2BR!$A$2:$B$13,2,FALSE) -> 4374 | M6: =C6*A6/12 -> 19894.5 | N6: =M6-L6 -> 15520.5
M12: 2 bedroom is key

Sheet New Data
A1: Affordable Housing Area Media Income (AMI)
A3: ize | B3: 30% AMI | C3: 40% AMI | D3: 50% AMI | E3: 60% AMI | F3: 70% AMI | G3: 80% AMI | H3: 90% AMI | I3: 100% AMI | J3: 110% AMI | K3: 120% AMI | L3: 130% AMI | M3: 165% AMI
A4: Studio | B4: 850 | C4: 1134 | D4: 1417 | E4: 1701 | F4: 1984 | G4: 2268 | H4: 2552 | I4: 2835 | J4: 3119 | K4: 3402 | L4: 3685 | M4: 4678
A5: One-bedroom | B5: 911 | C5: 1215 | D5: 1518 | E5: 1822 | F5: 2126 | G5: 2430 | H5: 2733 | I5: 3037 | J5: 3341 | K5: 3644 | L5: 3948 | M5: 5011
A6: Two-bedroom | B6: 1093 | C6: 1458 | D6: 1822 | E6: 2187 | F6: 2551 | G6: 2916 | H6: 3281 | I6: 3645 | J6: 4010 | K6: 4374 | L6: 4738 | M6: 6014
A13: FAMILY SIZE | B13: 0.3 | C13: 0.4 | D13: 0.5 | E13: 0.6 | F13: 0.7 | G13: 0.8 | H13: 0.9 | I13: 1 | J13: 1.1 | K13: 1.2 | L13: 1.3 | M13: 1.65
A14: 1 | B14: 34020 | C14: 45360 | D14: 56700 | E14: 68040 | F14: 79380 | G14: 90720 | H14: 102060 | I14: 113400 | J14: 124740 | K14: 136080 | L14: 147420 | M14: 187110
A15: 2 | B15: 38880 | C15: 51840 | D15: 64800 | E15: 77760 | F15: 90720 | G15: 103680 | H15: 116640 | I15: 129600 | J15: 142560 | K15: 155520 | L15: 168480 | M15: 213840
A16: 3 | B16: 43740 | C16: 58320 | D16: 72900 | E16: 87480 | F16: 102060 | G16: 116640 | H16: 131220 | I16: 145800 | J16: 160380 | K16: 174960 | L16: 189540 | M16: 240570
A17: 4 | B17: 48600 | C17: 64800 | D17: 81000 | E17: 97200 | F17: 113400 | G17: 129600 | H17: 145800 | I17: 162000 | J17: 178200 | K17: 194400 | L17: 210600 | M17: 267300

Sheet AMI_reference
A1: AMI_Level | B1: Required_Income_1_Person | C1: Required_Income_2_Person | D1: Required_Income_3_Person | E1: Required_Income_4_Person
A2: 0.3 | B2: 34020 | C2: 38880 | D2: 43740 | E2: 48600
A3: 0.4 | B3: 45360 | C3: 51840 | D3: 58320 | E3: 64800
A4: 0.6 | B4: 68040 | C4: 77760 | D4: 87480 | E4: 97200
A5: 0.8 | B5: 90720 | C5: 103680 | D5: 116640 | E5: 129600
A6: 1 | B6: 113400 | C6: 129600 | D6: 145800 | E6: 162000
A7: 1.2 | B7: 136080 | C7: 155520 | D7: 174960 | E7: 194400

Sheet Chart_Data
A1: AMI_Level | B1: HPD_Affordable_2BR_Rent_AMI | C1: CB1_Affordable_Rent_30pct
A2: =Summary!A2 -> 0.3 | B2: =Summary!L2 -> 1093 | C2: =Summary!M2 -> 4973.625
A3: =Summary!A3 -> 0.4 | B3: =Summary!L3 -> 1458 | C3: =Summary!M3 -> 6631.5
A4: =Summary!A4 -> 0.6 | B4: =Summary!L4 -> 2187 | C4: =Summary!M4 -> 9947.25
A5: =Summary!A5 -> 0.8 | B5: =Summary!L5 -> 2916 | C5: =Summary!M5 -> 13263
A6: =Summary!A6 -> 1.2 | B6: =Summary!L6 -> 4374 | C6: =Summary!M6 -> 19894.5

Sheet AMI_rent_2BR
A1: AMI_Level | B1: Max_Rent_2BR
A2: 0.3 | B2: 1093
A3: 0.4 | B3: 1458
A4: 0.5 | B4: 1822
A5: 0.6 | B5: 2187
A6: 0.7 | B6: 2551
A7: 0.8 | B7: 2916
A8: 0.9 | B8: 3281
A9: 1 | B9: 3645
A10: 1.1 | B10: 4010
A11: 1.2 | B11: 4374
A12: 1.3 | B12: 4738
A13: 1.65 | B13: 6014
